<sdf version='1.7'>
  <world name='default'>
    <light name='sun' type='directional'>
      <cast_shadows>1</cast_shadows>
      <pose>0 0 10 0 -0 0</pose>
      <diffuse>0.8 0.8 0.8 1</diffuse>
      <specular>0.2 0.2 0.2 1</specular>
      <attenuation>
        <range>1000</range>
        <constant>0.9</constant>
        <linear>0.01</linear>
        <quadratic>0.001</quadratic>
      </attenuation>
      <direction>-0.5 0.1 -0.9</direction>
      <spot>
        <inner_angle>0</inner_angle>
        <outer_angle>0</outer_angle>
        <falloff>0</falloff>
      </spot>
    </light>
    <model name='ground_plane'>
      <static>1</static>
      <link name='link'>
        <collision name='collision'>
          <geometry>
            <plane>
              <normal>0 0 1</normal>
              <size>100 100</size>
            </plane>
          </geometry>
          <surface>
            <contact>
              <collide_bitmask>65535</collide_bitmask>
              <ode/>
            </contact>
            <friction>
              <ode>
                <mu>100</mu>
                <mu2>50</mu2>
              </ode>
              <torsional>
                <ode/>
              </torsional>
            </friction>
            <bounce/>
          </surface>
          <max_contacts>10</max_contacts>
        </collision>
        <visual name='visual'>
          <cast_shadows>0</cast_shadows>
          <geometry>
            <plane>
              <normal>0 0 1</normal>
              <size>100 100</size>
            </plane>
          </geometry>
          <material>
            <script>
              <uri>file://media/materials/scripts/gazebo.material</uri>
              <name>Gazebo/Grey</name>
            </script>
          </material>
        </visual>
        <self_collide>0</self_collide>
        <enable_wind>0</enable_wind>
        <kinematic>0</kinematic>
      </link>
    </model>
    <gravity>0 0 -9.8</gravity>
    <magnetic_field>6e-06 2.3e-05 -4.2e-05</magnetic_field>
    <atmosphere type='adiabatic'/>
    <physics type='ode'>
      <max_step_size>0.001</max_step_size>
      <real_time_factor>1</real_time_factor>
      <real_time_update_rate>1000</real_time_update_rate>
    </physics>
    <scene>
      <ambient>0.4 0.4 0.4 1</ambient>
      <background>0.7 0.7 0.7 1</background>
      <shadows>1</shadows>
    </scene>
    <wind/>
    <spherical_coordinates>
      <surface_model>EARTH_WGS84</surface_model>
      <latitude_deg>0</latitude_deg>
      <longitude_deg>0</longitude_deg>
      <elevation>0</elevation>
      <heading_deg>0</heading_deg>
    </spherical_coordinates>
    <model name='maze'>
      <pose>0.91729 3.82141 0 0 -0 0</pose>
      <link name='Wall_26'>
        <collision name='Wall_26_Collision'>
          <geometry>
            <box>
              <size>10 0.15 2.5</size>
            </box>
          </geometry>
          <pose>0 0 1.25 0 -0 0</pose>
          <max_contacts>10</max_contacts>
          <surface>
            <contact>
              <ode/>
            </contact>
            <bounce/>
            <friction>
              <torsional>
                <ode/>
              </torsional>
              <ode/>
            </friction>
          </surface>
        </collision>
        <visual name='Wall_26_Visual'>
          <pose>0 0 1.25 0 -0 0</pose>
          <geometry>
            <box>
              <size>10 0.15 2.5</size>
            </box>
          </geometry>
          <material>
            <script>
              <uri>file://media/materials/scripts/gazebo.material</uri>
              <name>Gazebo/Grey</name>
            </script>
            <ambient>1 1 1 1</ambient>
          </material>
          <meta>
            <layer>0</layer>
          </meta>
        </visual>
        <pose>0 -4.67846 0 0 -0 0</pose>
        <self_collide>0</self_collide>
        <enable_wind>0</enable_wind>
        <kinematic>0</kinematic>
      </link>
      <link name='Wall_27'>
        <collision name='Wall_27_Collision'>
          <geometry>
            <box>
              <size>9.5 0.15 2.5</size>
            </box>
          </geometry>
          <pose>0 0 1.25 0 -0 0</pose>
          <max_contacts>10</max_contacts>
          <surface>
            <contact>
              <ode/>
            </contact>
            <bounce/>
            <friction>
              <torsional>
                <ode/>
              </torsional>
              <ode/>
            </friction>
          </surface>
        </collision>
        <visual name='Wall_27_Visual'>
          <pose>0 0 1.25 0 -0 0</pose>
          <geometry>
            <box>
              <size>9.5 0.15 2.5</size>
            </box>
          </geometry>
          <material>
            <script>
              <uri>file://media/materials/scripts/gazebo.material</uri>
              <name>Gazebo/Grey</name>
            </script>
            <ambient>1 1 1 1</ambient>
          </material>
          <meta>
            <layer>0</layer>
          </meta>
        </visual>
        <pose>4.925 -0.003461 0 0 -0 1.5708</pose>
        <self_collide>0</self_collide>
        <enable_wind>0</enable_wind>
        <kinematic>0</kinematic>
      </link>
      <link name='Wall_28'>
        <collision name='Wall_28_Collision'>
          <geometry>
            <box>
              <size>10 0.15 2.5</size>
            </box>
          </geometry>
          <pose>0 0 1.25 0 -0 0</pose>
          <max_contacts>10</max_contacts>
          <surface>
            <contact>
              <ode/>
            </contact>
            <bounce/>
            <friction>
              <torsional>
                <ode/>
              </torsional>
              <ode/>
            </friction>
          </surface>
        </collision>
        <visual name='Wall_28_Visual'>
          <pose>0 0 1.25 0 -0 0</pose>
          <geometry>
            <box>
              <size>10 0.15 2.5</size>
            </box>
          </geometry>
          <material>
            <script>
              <uri>file://media/materials/scripts/gazebo.material</uri>
              <name>Gazebo/Grey</name>
            </script>
            <ambient>1 1 1 1</ambient>
          </material>
          <meta>
            <layer>0</layer>
          </meta>
        </visual>
        <pose>0 4.67154 0 0 -0 3.14159</pose>
        <self_collide>0</self_collide>
        <enable_wind>0</enable_wind>
        <kinematic>0</kinematic>
      </link>
      <link name='Wall_29'>
        <collision name='Wall_29_Collision'>
          <geometry>
            <box>
              <size>9.5 0.15 2.5</size>
            </box>
          </geometry>
          <pose>0 0 1.25 0 -0 0</pose>
          <max_contacts>10</max_contacts>
          <surface>
            <contact>
              <ode/>
            </contact>
            <bounce/>
            <friction>
              <torsional>
                <ode/>
              </torsional>
              <ode/>
            </friction>
          </surface>
        </collision>
        <visual name='Wall_29_Visual'>
          <pose>0 0 1.25 0 -0 0</pose>
          <geometry>
            <box>
              <size>9.5 0.15 2.5</size>
            </box>
          </geometry>
          <material>
            <script>
              <uri>file://media/materials/scripts/gazebo.material</uri>
              <name>Gazebo/Grey</name>
            </script>
            <ambient>1 1 1 1</ambient>
          </material>
          <meta>
            <layer>0</layer>
          </meta>
        </visual>
        <pose>-4.925 -0.003461 0 0 -0 -1.5708</pose>
        <self_collide>0</self_collide>
        <enable_wind>0</enable_wind>
        <kinematic>0</kinematic>
      </link>
      <link name='Wall_36'>
        <collision name='Wall_36_Collision'>
          <geometry>
            <box>
              <size>3 0.15 2.5</size>
            </box>
          </geometry>
          <pose>0 0 1.25 0 -0 0</pose>
          <max_contacts>10</max_contacts>
          <surface>
            <contact>
              <ode/>
            </contact>
            <bounce/>
            <friction>
              <torsional>
                <ode/>
              </torsional>
              <ode/>
            </friction>
          </surface>
        </collision>
        <visual name='Wall_36_Visual'>
          <pose>0 0 1.25 0 -0 0</pose>
          <geometry>
            <box>
              <size>3 0.15 2.5</size>
            </box>
          </geometry>
          <material>
            <script>
              <uri>file://media/materials/scripts/gazebo.material</uri>
              <name>Gazebo/Grey</name>
            </script>
            <ambient>1 1 1 1</ambient>
          </material>
          <meta>
            <layer>0</layer>
          </meta>
        </visual>
        <pose>-3.49849 -0.40166 0 0 -0 0</pose>
        <self_collide>0</self_collide>
        <enable_wind>0</enable_wind>
        <kinematic>0</kinematic>
      </link>
      <link name='Wall_38'>
        <collision name='Wall_38_Collision'>
          <geometry>
            <box>
              <size>3 0.15 2.5</size>
            </box>
          </geometry>
          <pose>0 0 1.25 0 -0 0</pose>
          <max_contacts>10</max_contacts>
          <surface>
            <contact>
              <ode/>
            </contact>
            <bounce/>
            <friction>
              <torsional>
                <ode/>
              </torsional>
              <ode/>
            </friction>
          </surface>
        </collision>
        <visual name='Wall_38_Visual'>
          <pose>0 0 1.25 0 -0 0</pose>
          <geometry>
            <box>
              <size>3 0.15 2.5</size>
            </box>
          </geometry>
          <material>
            <script>
              <uri>file://media/materials/scripts/gazebo.material</uri>
              <name>Gazebo/Grey</name>
            </script>
            <ambient>1 1 1 1</ambient>
          </material>
          <meta>
            <layer>0</layer>
          </meta>
        </visual>
        <pose>-3.49609 -3.05214 0 0 -0 0</pose>
        <self_collide>0</self_collide>
        <enable_wind>0</enable_wind>
        <kinematic>0</kinematic>
      </link>
      <link name='Wall_39'>
        <collision name='Wall_39_Collision'>
          <geometry>
            <box>
              <size>1.75 0.15 2.5</size>
            </box>
          </geometry>
          <pose>0 0 1.25 0 -0 0</pose>
          <max_contacts>10</max_contacts>
          <surface>
            <contact>
              <ode/>
            </contact>
            <bounce/>
            <friction>
              <torsional>
                <ode/>
              </torsional>
              <ode/>
            </friction>
          </surface>
        </collision>
        <visual name='Wall_39_Visual'>
          <pose>0 0 1.25 0 -0 0</pose>
          <geometry>
            <box>
              <size>1.75 0.15 2.5</size>
            </box>
          </geometry>
          <material>
            <script>
              <uri>file://media/materials/scripts/gazebo.material</uri>
              <name>Gazebo/Grey</name>
            </script>
            <ambient>1 1 1 1</ambient>
          </material>
          <meta>
            <layer>0</layer>
          </meta>
        </visual>
        <pose>-2.07109 -2.25214 0 0 -0 1.5708</pose>
        <self_collide>0</self_collide>
        <enable_wind>0</enable_wind>
        <kinematic>0</kinematic>
      </link>
      <link name='Wall_43'>
        <collision name='Wall_43_Collision'>
          <geometry>
            <box>
              <size>4.25 0.15 2.5</size>
            </box>
          </geometry>
          <pose>0 0 1.25 0 -0 0</pose>
          <max_contacts>10</max_contacts>
          <surface>
            <contact>
              <ode/>
            </contact>
            <bounce/>
            <friction>
              <torsional>
                <ode/>
              </torsional>
              <ode/>
            </friction>
          </surface>
        </collision>
        <visual name='Wall_43_Visual'>
          <pose>0 0 1.25 0 -0 0</pose>
          <geometry>
            <box>
              <size>4.25 0.15 2.5</size>
            </box>
          </geometry>
          <material>
            <script>
              <uri>file://media/materials/scripts/gazebo.material</uri>
              <name>Gazebo/Grey</name>
            </script>
            <ambient>1 1 1 1</ambient>
          </material>
          <meta>
            <layer>0</layer>
          </meta>
        </visual>
        <pose>-2.0495 2.62846 0 0 -0 1.5708</pose>
        <self_collide>0</self_collide>
        <enable_wind>0</enable_wind>
        <kinematic>0</kinematic>
      </link>
      <link name='Wall_45'>
        <collision name='Wall_45_Collision'>
          <geometry>
            <box>
              <size>2 0.15 2.5</size>
            </box>
          </geometry>
          <pose>0 0 1.25 0 -0 0</pose>
          <max_contacts>10</max_contacts>
          <surface>
            <contact>
              <ode/>
            </contact>
            <bounce/>
            <friction>
              <torsional>
                <ode/>
              </torsional>
              <ode/>
            </friction>
          </surface>
        </collision>
        <visual name='Wall_45_Visual'>
          <pose>0 0 1.25 0 -0 0</pose>
          <geometry>
            <box>
              <size>2 0.15 2.5</size>
            </box>
          </geometry>
          <material>
            <script>
              <uri>file://media/materials/scripts/gazebo.material</uri>
              <name>Gazebo/Grey</name>
            </script>
            <ambient>1 1 1 1</ambient>
          </material>
          <meta>
            <layer>0</layer>
          </meta>
        </visual>
        <pose>-3.98979 2.47772 0 0 -0 0</pose>
        <self_collide>0</self_collide>
        <enable_wind>0</enable_wind>
        <kinematic>0</kinematic>
      </link>
      <link name='Wall_47'>
        <collision name='Wall_47_Collision'>
          <geometry>
            <box>
              <size>2.5 0.15 2.5</size>
            </box>
          </geometry>
          <pose>0 0 1.25 0 -0 0</pose>
          <max_contacts>10</max_contacts>
          <surface>
            <contact>
              <ode/>
            </contact>
            <bounce/>
            <friction>
              <torsional>
                <ode/>
              </torsional>
              <ode/>
            </friction>
          </surface>
        </collision>
        <visual name='Wall_47_Visual'>
          <pose>0 0 1.25 0 -0 0</pose>
          <geometry>
            <box>
              <size>2.5 0.15 2.5</size>
            </box>
          </geometry>
          <material>
            <script>
              <uri>file://media/materials/scripts/gazebo.material</uri>
              <name>Gazebo/Grey</name>
            </script>
            <ambient>1 1 1 1</ambient>
          </material>
          <meta>
            <layer>0</layer>
          </meta>
        </visual>
        <pose>0.097423 1.87505 0 0 -0 -1.5708</pose>
        <self_collide>0</self_collide>
        <enable_wind>0</enable_wind>
        <kinematic>0</kinematic>
      </link>
      <link name='Wall_48'>
        <collision name='Wall_48_Collision'>
          <geometry>
            <box>
              <size>1.5 0.15 2.5</size>
            </box>
          </geometry>
          <pose>0 0 1.25 0 -0 0</pose>
          <max_contacts>10</max_contacts>
          <surface>
            <contact>
              <ode/>
            </contact>
            <bounce/>
            <friction>
              <torsional>
                <ode/>
              </torsional>
              <ode/>
            </friction>
          </surface>
        </collision>
        <visual name='Wall_48_Visual'>
          <pose>0 0 1.25 0 -0 0</pose>
          <geometry>
            <box>
              <size>1.5 0.15 2.5</size>
            </box>
          </geometry>
          <material>
            <script>
              <uri>file://media/materials/scripts/gazebo.material</uri>
              <name>Gazebo/Grey</name>
            </script>
            <ambient>1 1 1 1</ambient>
          </material>
          <meta>
            <layer>0</layer>
          </meta>
        </visual>
        <pose>0.772423 0.700048 0 0 -0 0</pose>
        <self_collide>0</self_collide>
        <enable_wind>0</enable_wind>
        <kinematic>0</kinematic>
      </link>
      <link name='Wall_50'>
        <collision name='Wall_50_Collision'>
          <geometry>
            <box>
              <size>3.25 0.15 2.5</size>
            </box>
          </geometry>
          <pose>0 0 1.25 0 -0 0</pose>
          <max_contacts>10</max_contacts>
          <surface>
            <contact>
              <ode/>
            </contact>
            <bounce/>
            <friction>
              <torsional>
                <ode/>
              </torsional>
              <ode/>
            </friction>
          </surface>
        </collision>
        <visual name='Wall_50_Visual'>
          <pose>0 0 1.25 0 -0 0</pose>
          <geometry>
            <box>
              <size>3.25 0.15 2.5</size>
            </box>
          </geometry>
          <material>
            <script>
              <uri>file://media/materials/scripts/gazebo.material</uri>
              <name>Gazebo/Grey</name>
            </script>
            <ambient>1 1 1 1</ambient>
          </material>
          <meta>
            <layer>0</layer>
          </meta>
        </visual>
        <pose>1.64742 3.05005 0 0 -0 0</pose>
        <self_collide>0</self_collide>
        <enable_wind>0</enable_wind>
        <kinematic>0</kinematic>
      </link>
      <link name='Wall_51'>
        <collision name='Wall_51_Collision'>
          <geometry>
            <box>
              <size>2.5 0.15 2.5</size>
            </box>
          </geometry>
          <pose>0 0 1.25 0 -0 0</pose>
          <max_contacts>10</max_contacts>
          <surface>
            <contact>
              <ode/>
            </contact>
            <bounce/>
            <friction>
              <torsional>
                <ode/>
              </torsional>
              <ode/>
            </friction>
          </surface>
        </collision>
        <visual name='Wall_51_Visual'>
          <pose>0 0 1.25 0 -0 0</pose>
          <geometry>
            <box>
              <size>2.5 0.15 2.5</size>
            </box>
          </geometry>
          <material>
            <script>
              <uri>file://media/materials/scripts/gazebo.material</uri>
              <name>Gazebo/Grey</name>
            </script>
            <ambient>1 1 1 1</ambient>
          </material>
          <meta>
            <layer>0</layer>
          </meta>
        </visual>
        <pose>3.19742 1.87505 0 0 -0 -1.5708</pose>
        <self_collide>0</self_collide>
        <enable_wind>0</enable_wind>
        <kinematic>0</kinematic>
      </link>
      <link name='Wall_53'>
        <collision name='Wall_53_Collision'>
          <geometry>
            <box>
              <size>4.5 0.15 2.5</size>
            </box>
          </geometry>
          <pose>0 0 1.25 0 -0 0</pose>
          <max_contacts>10</max_contacts>
          <surface>
            <contact>
              <ode/>
            </contact>
            <bounce/>
            <friction>
              <torsional>
                <ode/>
              </torsional>
              <ode/>
            </friction>
          </surface>
        </collision>
        <visual name='Wall_53_Visual'>
          <pose>0 0 1.25 0 -0 0</pose>
          <geometry>
            <box>
              <size>4.5 0.15 2.5</size>
            </box>
          </geometry>
          <material>
            <script>
              <uri>file://media/materials/scripts/gazebo.material</uri>
              <name>Gazebo/Grey</name>
            </script>
            <ambient>1 1 1 1</ambient>
          </material>
          <meta>
            <layer>0</layer>
          </meta>
        </visual>
        <pose>0.120423 -2.50295 0 0 -0 1.5708</pose>
        <self_collide>0</self_collide>
        <enable_wind>0</enable_wind>
        <kinematic>0</kinematic>
      </link>
      <link name='Wall_55'>
        <collision name='Wall_55_Collision'>
          <geometry>
            <box>
              <size>3.25 0.15 2.5</size>
            </box>
          </geometry>
          <pose>0 0 1.25 0 -0 0</pose>
          <max_contacts>10</max_contacts>
          <surface>
            <contact>
              <ode/>
            </contact>
            <bounce/>
            <friction>
              <torsional>
                <ode/>
              </torsional>
              <ode/>
            </friction>
          </surface>
        </collision>
        <visual name='Wall_55_Visual'>
          <pose>0 0 1.25 0 -0 0</pose>
          <geometry>
            <box>
              <size>3.25 0.15 2.5</size>
            </box>
          </geometry>
          <material>
            <script>
              <uri>file://media/materials/scripts/gazebo.material</uri>
              <name>Gazebo/Grey</name>
            </script>
            <ambient>1 1 1 1</ambient>
          </material>
          <meta>
            <layer>0</layer>
          </meta>
        </visual>
        <pose>1.67042 -2.19395 0 0 -0 0</pose>
        <self_collide>0</self_collide>
        <enable_wind>0</enable_wind>
        <kinematic>0</kinematic>
      </link>
      <static>1</static>
    </model>
    <state world_name='default'>
      <sim_time>390 664000000</sim_time>
      <real_time>79 692571845</real_time>
      <wall_time>1739173952 843373271</wall_time>
      <iterations>42124</iterations>
      <model name='ground_plane'>
        <pose>0 0 0 0 -0 0</pose>
        <scale>1 1 1</scale>
        <link name='link'>
          <pose>0 0 0 0 -0 0</pose>
          <velocity>0 0 0 0 -0 0</velocity>
          <acceleration>0 0 0 0 -0 0</acceleration>
          <wrench>0 0 0 0 -0 0</wrench>
        </link>
      </model>
      <model name='maze'>
        <pose>0.91729 3.82141 0 0 -0 0</pose>
        <scale>1 1 1</scale>
        <link name='Wall_26'>
          <pose>0.91729 -0.85705 0 0 -0 0</pose>
          <velocity>0 0 0 0 -0 0</velocity>
          <acceleration>0 0 0 0 -0 0</acceleration>
          <wrench>0 0 0 0 -0 0</wrench>
        </link>
        <link name='Wall_27'>
          <pose>5.84229 3.81795 0 0 -0 1.5708</pose>
          <velocity>0 0 0 0 -0 0</velocity>
          <acceleration>0 0 0 0 -0 0</acceleration>
          <wrench>0 0 0 0 -0 0</wrench>
        </link>
        <link name='Wall_28'>
          <pose>0.91729 8.49295 0 0 -0 3.14159</pose>
          <velocity>0 0 0 0 -0 0</velocity>
          <acceleration>0 0 0 0 -0 0</acceleration>
          <wrench>0 0 0 0 -0 0</wrench>
        </link>
        <link name='Wall_29'>
          <pose>-4.00771 3.81795 0 0 0 -1.5708</pose>
          <velocity>0 0 0 0 -0 0</velocity>
          <acceleration>0 0 0 0 -0 0</acceleration>
          <wrench>0 0 0 0 -0 0</wrench>
        </link>
        <link name='Wall_36'>
          <pose>-2.5812 3.41975 0 0 -0 0</pose>
          <velocity>0 0 0 0 -0 0</velocity>
          <acceleration>0 0 0 0 -0 0</acceleration>
          <wrench>0 0 0 0 -0 0</wrench>
        </link>
        <link name='Wall_38'>
          <pose>-2.5788 0.76927 0 0 -0 0</pose>
          <velocity>0 0 0 0 -0 0</velocity>
          <acceleration>0 0 0 0 -0 0</acceleration>
          <wrench>0 0 0 0 -0 0</wrench>
        </link>
        <link name='Wall_39'>
          <pose>-1.1538 1.56927 0 0 -0 1.5708</pose>
          <velocity>0 0 0 0 -0 0</velocity>
          <acceleration>0 0 0 0 -0 0</acceleration>
          <wrench>0 0 0 0 -0 0</wrench>
        </link>
        <link name='Wall_43'>
          <pose>-1.13221 6.44987 0 0 -0 1.5708</pose>
          <velocity>0 0 0 0 -0 0</velocity>
          <acceleration>0 0 0 0 -0 0</acceleration>
          <wrench>0 0 0 0 -0 0</wrench>
        </link>
        <link name='Wall_45'>
          <pose>-3.0725 6.29913 0 0 -0 0</pose>
          <velocity>0 0 0 0 -0 0</velocity>
          <acceleration>0 0 0 0 -0 0</acceleration>
          <wrench>0 0 0 0 -0 0</wrench>
        </link>
        <link name='Wall_47'>
          <pose>1.01471 5.69646 0 0 0 -1.5708</pose>
          <velocity>0 0 0 0 -0 0</velocity>
          <acceleration>0 0 0 0 -0 0</acceleration>
          <wrench>0 0 0 0 -0 0</wrench>
        </link>
        <link name='Wall_48'>
          <pose>1.68971 4.52146 0 0 -0 0</pose>
          <velocity>0 0 0 0 -0 0</velocity>
          <acceleration>0 0 0 0 -0 0</acceleration>
          <wrench>0 0 0 0 -0 0</wrench>
        </link>
        <link name='Wall_50'>
          <pose>2.56471 6.87146 0 0 -0 0</pose>
          <velocity>0 0 0 0 -0 0</velocity>
          <acceleration>0 0 0 0 -0 0</acceleration>
          <wrench>0 0 0 0 -0 0</wrench>
        </link>
        <link name='Wall_51'>
          <pose>4.11471 5.69646 0 0 0 -1.5708</pose>
          <velocity>0 0 0 0 -0 0</velocity>
          <acceleration>0 0 0 0 -0 0</acceleration>
          <wrench>0 0 0 0 -0 0</wrench>
        </link>
        <link name='Wall_53'>
          <pose>1.03771 1.31846 0 0 -0 1.5708</pose>
          <velocity>0 0 0 0 -0 0</velocity>
          <acceleration>0 0 0 0 -0 0</acceleration>
          <wrench>0 0 0 0 -0 0</wrench>
        </link>
        <link name='Wall_55'>
          <pose>2.58771 1.62746 0 0 -0 0</pose>
          <velocity>0 0 0 0 -0 0</velocity>
          <acceleration>0 0 0 0 -0 0</acceleration>
          <wrench>0 0 0 0 -0 0</wrench>
        </link>
      </model>
      <model name='omni_robot0'>
        <pose>-0.004152 -0.009003 0.040267 -0.00016 -0.000187 0.155391</pose>
        <scale>1 1 1</scale>
        <link name='base_footprint'>
          <pose>-0.004152 -0.009003 0.040267 -0.00016 -0.000187 0.155391</pose>
          <velocity>0.000201 -0.000189 0.003994 -0.015334 -0.002676 0.003262</velocity>
          <acceleration>0.158606 -0.33164 9.3542 -1.39251 -0.665297 -1.11426</acceleration>
          <wrench>0.186045 -0.389014 10.9725 0 -0 0</wrench>
        </link>
        <link name='first_wheel_link'>
          <pose>-0.017769 0.077935 0.030255 0.000191 0.004873 -2.9862</pose>
          <velocity>-3.7e-05 -0.000428 0.002942 -0.020283 -0.003607 0.00341</velocity>
          <acceleration>0.294876 -0.392002 9.8285 -3.08504 0.158233 2.16687</acceleration>
          <wrench>0.073719 -0.098 2.45712 0 -0 0</wrench>
        </link>
        <link name='main_camera_bracket_link'>
          <pose>-0.00416 -0.008998 0.079267 -0.000187 0.000168 1.72603</pose>
          <velocity>8.4e-05 0.000467 0.003977 -0.016472 -0.002833 0.003278</velocity>
          <acceleration>0.04454 0.097761 9.30407 -2.61505 -1.35913 -1.09782</acceleration>
          <wrench>0.004899 0.010754 1.02345 0 -0 0</wrench>
        </link>
        <link name='r10_F_roller_link'>
          <pose>0.005804 0.075553 0.022932 1.26223 -0.021452 -1.482</pose>
          <velocity>-1e-06 -0.000497 0.003106 -0.018172 -0.003274 0.010025</velocity>
          <acceleration>0.302444 -0.507754 10.1279 1.78329 -0.612496 -2.54509</acceleration>
          <wrench>0.002722 -0.00457 0.091151 0 -0 0</wrench>
        </link>
        <link name='r10_S_roller_link'>
          <pose>-0.082081 -0.042991 0.021726 1.20837 -0.012977 0.645047</pose>
          <velocity>0.000405 -0.000711 0.004624 -0.014743 -0.006338 0.00445</velocity>
          <acceleration>0.225384 -0.242985 10.0517 0.257998 -0.80192 -0.863718</acceleration>
          <wrench>0.002028 -0.002187 0.090465 0 -0 0</wrench>
        </link>
        <link name='r10_T_roller_link'>
          <pose>0.064102 -0.059889 0.022904 1.25962 -0.021467 2.70604</pose>
          <velocity>0.000388 -0.000212 0.005189 -0.014257 0.000309 0.002462</velocity>
          <acceleration>0.063703 -0.423661 9.91904 -0.208455 0.44154 -3.01903</acceleration>
          <wrench>0.000573 -0.003813 0.089271 0 -0 0</wrench>
        </link>
        <link name='r1_F_roller_link'>
          <pose>-0.018815 0.083849 0.054317 0.004874 -0.018675 -1.41549</pose>
          <velocity>-0.000144 5.7e-05 0.002854 -0.00065 -0.000583 0.003501</velocity>
          <acceleration>0.227318 -0.093743 9.97435 0.319763 -0.156386 -0.91436</acceleration>
          <wrench>0.002046 -0.000844 0.089769 0 -0 0</wrench>
        </link>
        <link name='r1_S_roller_link'>
          <pose>-0.078026 -0.067129 0.054296 -0.048513 0.028082 0.677622</pose>
          <velocity>0.000269 -0.000228 0.005004 -0.012782 -0.00869 0.003503</velocity>
          <acceleration>-0.046687 -0.312856 10.047 -1.2088 1.29646 1.51568</acceleration>
          <wrench>-0.00042 -0.002816 0.090423 0 -0 0</wrench>
        </link>
        <link name='r1_T_roller_link'>
          <pose>0.083554 -0.042788 0.054354 0.002268 -0.007857 2.77337</pose>
          <velocity>0.000337 0.000304 0.004946 -0.012388 0.005293 0.003278</velocity>
          <acceleration>0.22996 -0.450803 9.84324 -1.72661 -0.754268 -0.977647</acceleration>
          <wrench>0.00207 -0.004057 0.088589 0 -0 0</wrench>
        </link>
        <link name='r2_F_roller_link'>
          <pose>0.003875 0.0874 0.037802 -1.25226 0.01814 -1.47093</pose>
          <velocity>-9.6e-05 -0.000201 0.00287 -0.018676 -0.003406 -0.001662</velocity>
          <acceleration>0.27399 -0.321539 10.002 1.15878 -0.670697 2.18436</acceleration>
          <wrench>0.002466 -0.002894 0.090018 0 -0 0</wrench>
        </link>
        <link name='r2_S_roller_link'>
          <pose>-0.091873 -0.049967 0.036579 -1.30549 0.013932 0.627392</pose>
          <velocity>0.00033 -0.00053 0.004669 -0.01394 -0.00725 0.006069</velocity>
          <acceleration>0.106398 -0.262308 9.98746 1.40548 -1.4027 1.57845</acceleration>
          <wrench>0.000958 -0.002361 0.089887 0 -0 0</wrench>
        </link>
        <link name='r2_T_roller_link'>
          <pose>0.075307 -0.064176 0.037779 -1.25503 0.020768 2.71061</pose>
          <velocity>0.000405 3.8e-05 0.00526 -0.014086 0.000888 0.005707</velocity>
          <acceleration>0.130544 -0.438213 9.88645 -0.089301 0.498249 2.36472</acceleration>
          <wrench>0.001175 -0.003944 0.088978 0 -0 0</wrench>
        </link>
        <link name='r3_F_roller_link'>
          <pose>-0.00463 0.086063 0.010856 -0.823685 0.632515 1.15825</pose>
          <velocity>1e-05 -0.000779 0.002871 -0.786461 0.058894 2.20885</velocity>
          <acceleration>0.349343 -0.649314 10.0082 -0.130303 -1.4809 2.53121</acceleration>
          <wrench>0.003144 -0.005844 0.090074 0 -0 0</wrench>
        </link>
        <link name='r3_S_roller_link'>
          <pose>-0.085569 -0.057775 0.010131 -1.17938 0.93638 2.72339</pose>
          <velocity>0.000532 -0.000888 0.004829 -1.86462 -0.441819 0.32057</velocity>
          <acceleration>0.294928 -0.211824 10.0296 -3.12582 1.21094 -0.068107</acceleration>
          <wrench>0.002654 -0.001906 0.090267 0 -0 0</wrench>
        </link>
        <link name='r3_T_roller_link'>
          <pose>0.078437 -0.05608 0.010856 -2.29038 -0.669737 2.15689</pose>
          <velocity>0.000373 -0.00034 0.005148 -2.00761 0.166251 0.816731</velocity>
          <acceleration>0.00761 -0.437484 9.88346 -1.75291 -1.37319 2.83723</acceleration>
          <wrench>6.8e-05 -0.003937 0.088951 0 -0 0</wrench>
        </link>
        <link name='r4_F_roller_link'>
          <pose>-0.032577 0.081685 0.010719 2.49244 -0.262291 -1.22125</pose>
          <velocity>2.5e-05 -0.000877 0.00286 -0.507778 0.520682 -0.239858</velocity>
          <acceleration>0.344118 -0.624328 9.99481 2.0643 -0.808162 -0.650185</acceleration>
          <wrench>0.003097 -0.005619 0.089953 0 -0 0</wrench>
        </link>
        <link name='r4_S_roller_link'>
          <pose>-0.067825 -0.079763 0.011503 1.45445 -0.8885 2.39917</pose>
          <velocity>0.000598 -0.000808 0.005267 0.151948 -0.480265 -0.523669</velocity>
          <acceleration>0.260705 -0.235257 10.1239 -3.01835 1.23678 -2.38633</acceleration>
          <wrench>0.002346 -0.002117 0.091115 0 -0 0</wrench>
        </link>
        <link name='r4_T_roller_link'>
          <pose>0.088619 -0.029688 0.010792 1.61969 -0.943877 -1.99917</pose>
          <velocity>0.000286 -0.000307 0.004769 0.207076 -0.678943 -2.84659</velocity>
          <acceleration>0.03319 -0.445975 9.84711 1.78864 -0.452648 -0.696383</acceleration>
          <wrench>0.000299 -0.004014 0.088624 0 -0 0</wrench>
        </link>
        <link name='r5_F_roller_link'>
          <pose>-0.041343 0.080317 0.037579 1.26224 -0.021479 -1.48208</pose>
          <velocity>-7e-05 -0.00036 0.002861 -0.01827 -0.003394 0.010068</velocity>
          <acceleration>0.268627 -0.278602 9.99985 1.56904 -0.686647 -2.43699</acceleration>
          <wrench>0.002418 -0.002507 0.089999 0 -0 0</wrench>
        </link>
        <link name='r5_S_roller_link'>
          <pose>-0.063163 -0.085544 0.038798 1.20835 -0.012297 0.64684</pose>
          <velocity>0.000434 -0.000401 0.005386 -0.014612 -0.00634 0.004557</velocity>
          <acceleration>0.047713 -0.299157 10.1566 0.58111 -0.807216 -0.751364</acceleration>
          <wrench>0.000429 -0.002692 0.091409 0 -0 0</wrench>
        </link>
        <link name='r5_T_roller_link'>
          <pose>0.091781 -0.021473 0.037675 1.25963 -0.021508 2.70591</pose>
          <velocity>0.000265 9e-05 0.004656 -0.014306 0.000459 0.002481</velocity>
          <acceleration>0.172771 -0.455447 9.84374 -0.312743 0.474173 -2.78808</acceleration>
          <wrench>0.001555 -0.004099 0.088594 0 -0 0</wrench>
        </link>
        <link name='r6_F_roller_link'>
          <pose>-0.016724 0.07202 0.006253 0.005948 -0.547739 -1.4185</pose>
          <velocity>0.000628 -0.002159 0.011659 0.34616 0.100354 0.004249</velocity>
          <acceleration>0.875137 -1.95483 30.4418 1.99349 -0.838333 -2.48419</acceleration>
          <wrench>0.007876 -0.017593 0.273977 0 -0 0</wrench>
        </link>
        <link name='r6_S_roller_link'>
          <pose>-0.067216 -0.061407 0.00627 -2.95219 1.31263 -2.27936</pose>
          <velocity>0.000789 -0.0002 0.012943 0.030236 0.131403 -0.012423</velocity>
          <acceleration>1.09174 0.12777 26.6086 1.88244 1.14634 -1.47381</acceleration>
          <wrench>0.009826 0.00115 0.239477 0 -0 0</wrench>
        </link>
        <link name='r6_T_roller_link'>
          <pose>0.072327 -0.038578 0.006264 3.1391 -0.465655 -0.367073</pose>
          <velocity>0.000156 -0.000282 0.012806 0.048441 0.019519 0.005202</velocity>
          <acceleration>-0.696547 -1.10025 25.5977 1.50941 -0.904677 -0.829932</acceleration>
          <wrench>-0.006269 -0.009902 0.230379 0 -0 0</wrench>
        </link>
        <link name='r7_F_roller_link'>
          <pose>-0.039414 0.06847 0.022706 -1.25199 0.012086 -1.45246</pose>
          <velocity>-7e-06 -0.000565 0.002603 -0.013438 -0.002557 0.001221</velocity>
          <acceleration>0.253261 -0.313977 8.97242 0.893179 -0.081984 0.245488</acceleration>
          <wrench>0.002279 -0.002826 0.080752 0 -0 0</wrench>
        </link>
        <link name='r7_S_roller_link'>
          <pose>-0.053371 -0.078568 0.023942 -1.30563 0.016352 0.618585</pose>
          <velocity>0.000485 -0.000619 0.004892 -0.01732 -0.003462 0.00677</velocity>
          <acceleration>0.10176 -0.331911 9.29234 1.66028 0.084247 1.05743</acceleration>
          <wrench>0.000916 -0.002987 0.083631 0 -0 0</wrench>
        </link>
        <link name='r7_T_roller_link'>
          <pose>0.080577 -0.017187 0.022798 -1.25474 0.015431 2.72702</pose>
          <velocity>0.000286 -0.000179 0.004133 -0.015828 -0.003138 0.008164</velocity>
          <acceleration>0.190745 -0.461218 8.98546 -3.00242 -0.423474 -2.58899</acceleration>
          <wrench>0.001717 -0.004151 0.080869 0 -0 0</wrench>
        </link>
        <link name='r8_F_roller_link'>
          <pose>-0.030908 0.069807 0.049651 -2.50791 -0.036523 -1.44211</pose>
          <velocity>-8.1e-05 -0.000155 0.002613 -0.00441 -0.001085 0.010471</velocity>
          <acceleration>0.252455 -0.352337 8.99135 1.01874 -0.039068 -1.27155</acceleration>
          <wrench>0.002272 -0.003171 0.080922 0 -0 0</wrench>
        </link>
        <link name='r8_S_roller_link'>
          <pose>-0.059675 -0.07076 0.05039 -2.56174 -0.008008 0.673794</pose>
          <velocity>0.000384 -0.000166 0.004741 -0.015021 -0.006395 0.000244</velocity>
          <acceleration>0.125805 -0.193555 9.27143 1.97892 0.507398 -1.81525</acceleration>
          <wrench>0.001132 -0.001742 0.083443 0 -0 0</wrench>
        </link>
        <link name='r8_T_roller_link'>
          <pose>0.077446 -0.025283 0.049721 -2.51066 -0.030551 2.75089</pose>
          <velocity>0.000191 0.000249 0.004257 -0.014148 0.001062 -0.001103</velocity>
          <acceleration>0.057891 -0.368048 9.01274 -1.54061 1.47334 1.36338</acceleration>
          <wrench>0.000521 -0.003312 0.081115 0 -0 0</wrench>
        </link>
        <link name='r9_F_roller_link'>
          <pose>-0.002962 0.074185 0.049789 2.51811 0.009354 -1.42224</pose>
          <velocity>-9.6e-05 -6.2e-05 0.002629 -0.006383 -0.001361 -0.002489</velocity>
          <acceleration>0.255746 -0.382196 9.01268 -0.114979 -0.062896 -0.321487</acceleration>
          <wrench>0.002302 -0.00344 0.081114 0 -0 0</wrench>
        </link>
        <link name='r9_S_roller_link'>
          <pose>-0.077419 -0.048772 0.049018 2.464 0.044007 0.643546</pose>
          <velocity>0.000315 -0.000249 0.004303 -0.014482 -0.007112 0.007642</velocity>
          <acceleration>0.148247 -0.183936 9.18502 2.1254 0.685263 -0.079174</acceleration>
          <wrench>0.001334 -0.001655 0.082665 0 -0 0</wrench>
        </link>
        <link name='r9_T_roller_link'>
          <pose>0.067264 -0.051675 0.049785 2.51538 0.020719 2.75859</pose>
          <velocity>0.00028 0.000217 0.004647 -0.013454 0.002772 0.008972</velocity>
          <acceleration>0.031166 -0.356566 9.06624 -1.50563 0.616453 2.48318</acceleration>
          <wrench>0.00028 -0.003209 0.081596 0 -0 0</wrench>
        </link>
        <link name='second_wheel_link'>
          <pose>-0.072622 -0.064268 0.030261 0.000101 -0.048495 -0.891814</pose>
          <velocity>0.00042 -0.000556 0.004965 -0.014487 -0.006678 0.003383</velocity>
          <acceleration>0.129662 -0.26119 9.94554 0.463797 1.2133 2.00737</acceleration>
          <wrench>0.032416 -0.065297 2.48639 0 -0 0</wrench>
        </link>
        <link name='third_wheel_link'>
          <pose>0.077942 -0.040681 0.030288 -0.000252 0.002267 1.20259</pose>
          <velocity>0.00033 -6.8e-05 0.004618 -0.016236 -0.004403 0.003299</velocity>
          <acceleration>0.125601 -0.446496 9.34133 -2.89706 -0.641533 -1.12887</acceleration>
          <wrench>0.0314 -0.111624 2.33533 0 -0 0</wrench>
        </link>
      </model>
      <light name='sun'>
        <pose>0 0 10 0 -0 0</pose>
      </light>
    </state>
    <gui fullscreen='0'>
      <camera name='user_camera'>
        <pose>-1.10603 -0.402487 1.25789 0 0.881804 0.728202</pose>
        <view_controller>orbit</view_controller>
        <projection_type>perspective</projection_type>
      </camera>
    </gui>
    <model name='omni_robot0'>
      <link name='base_footprint'>
        <inertial>
          <pose>0 0 0.000107 0 -0 0</pose>
          <mass>1.173</mass>
          <inertia>
            <ixx>0.00321563</ixx>
            <ixy>0</ixy>
            <ixz>0</ixz>
            <iyy>0.00321563</iyy>
            <iyz>0</iyz>
            <izz>0.00640002</izz>
          </inertia>
        </inertial>
        <collision name='base_footprint_fixed_joint_lump__base_link_collision'>
          <pose>0 0 0 0 -0 0</pose>
          <geometry>
            <mesh>
              <scale>1 1 1</scale>
              <uri>/home/yp7/catkin_ws/src/Omni_wheel_robot_GazeboSim/omni_robot_description/meshes/STL/base/base_link.stl</uri>
            </mesh>
          </geometry>
          <surface>
            <contact>
              <ode/>
            </contact>
            <friction>
              <ode>
                <mu>0.05</mu>
                <mu2>0.05</mu2>
              </ode>
              <torsional>
                <ode/>
              </torsional>
            </friction>
            <bounce/>
          </surface>
          <max_contacts>10</max_contacts>
        </collision>
        <collision name='base_footprint_fixed_joint_lump__first_base_layer_link_collision_1'>
          <pose>0 0 0.125 0 -0 0</pose>
          <geometry>
            <cylinder>
              <length>0.001</length>
              <radius>0.088</radius>
            </cylinder>
          </geometry>
          <max_contacts>10</max_contacts>
          <surface>
            <contact>
              <ode/>
            </contact>
            <bounce/>
            <friction>
              <torsional>
                <ode/>
              </torsional>
              <ode/>
            </friction>
          </surface>
        </collision>
        <visual name='base_footprint_fixed_joint_lump__base_link_visual'>
          <pose>0 0 0 0 -0 0</pose>
          <geometry>
            <mesh>
              <scale>1 1 1</scale>
              <uri>/home/yp7/catkin_ws/src/Omni_wheel_robot_GazeboSim/omni_robot_description/meshes/DAE/base/omni_wheel_body.dae</uri>
            </mesh>
          </geometry>
        </visual>
        <visual name='base_footprint_fixed_joint_lump__first_base_layer_link_visual_1'>
          <pose>0 0 0.125 0 -0 0</pose>
          <geometry>
            <cylinder>
              <length>0.003</length>
              <radius>0.1</radius>
            </cylinder>
          </geometry>
        </visual>
        <visual name='base_footprint_fixed_joint_lump__laser_scan_visual_2'>
          <pose>0 0 0.1315 0 -0 1.5707</pose>
          <geometry>
            <cylinder>
              <length>0.01</length>
              <radius>0.02</radius>
            </cylinder>
          </geometry>
          <material>
            <script>
              <name>Gazebo/Red</name>
              <uri>file://media/materials/scripts/gazebo.material</uri>
            </script>
          </material>
        </visual>
        <visual name='base_footprint_fixed_joint_lump__imu_link_visual_3'>
          <pose>0 0 0 0 -0 0</pose>
          <geometry>
            <mesh>
              <scale>1 1 1</scale>
              <uri>/home/yp7/catkin_ws/src/Omni_wheel_robot_GazeboSim/omni_robot_description/meshes/DAE/IMU/IMU_sensor.dae</uri>
            </mesh>
          </geometry>
        </visual>
        <self_collide>0</self_collide>
        <sensor name='laser_scan_sensor' type='ray'>
          <always_on>1</always_on>
          <update_rate>5</update_rate>
          <visualize>0</visualize>
          <ray>
            <scan>
              <horizontal>
                <samples>360</samples>
                <resolution>1</resolution>
                <min_angle>0</min_angle>
                <max_angle>6.28319</max_angle>
              </horizontal>
              <vertical>
                <samples>1</samples>
                <min_angle>0</min_angle>
                <max_angle>0</max_angle>
              </vertical>
            </scan>
            <range>
              <min>0.12</min>
              <max>5</max>
              <resolution>0.01</resolution>
            </range>
            <noise>
              <type>gaussian</type>
              <mean>0</mean>
              <stddev>0.01</stddev>
            </noise>
          </ray>
          <plugin name='laser_controller' filename='libgazebo_ros_laser.so'>
            <topicName>/scan</topicName>
            <frameName>laser_scan</frameName>
            <robotNamespace>/robot_omni/</robotNamespace>
          </plugin>
          <pose>0 0 0.1315 0 -0 1.5707</pose>
        </sensor>
        <gravity>1</gravity>
        <sensor name='imu_sensor' type='imu'>
          <always_on>1</always_on>
          <update_rate>0</update_rate>
          <visualize>1</visualize>
          <topic>imu/data</topic>
          <plugin name='imu_plugin' filename='libgazebo_ros_imu_sensor.so'>
            <topicName>imu/data</topicName>
            <update_rate>0</update_rate>
            <bodyName>imu_link</bodyName>
            <updateRateHZ>0</updateRateHZ>
            <gaussianNoise>0.0</gaussianNoise>
            <xyzOffset>0 0 0</xyzOffset>
            <rpyOffset>0 0 0</rpyOffset>
            <frameName>imu_link</frameName>
            <robotNamespace>/robot_omni/</robotNamespace>
          </plugin>
          <pose>0 0 0 0 -0 0</pose>
          <imu/>
        </sensor>
        <enable_wind>0</enable_wind>
        <kinematic>0</kinematic>
      </link>
      <joint name='first_wheel_joint' type='revolute'>
        <pose relative_to='base_footprint'>0 0.088 -0.01 0 0 -3.14159</pose>
        <parent>base_footprint</parent>
        <child>first_wheel_link</child>
        <axis>
          <xyz>0 1 0</xyz>
          <limit>
            <effort>100</effort>
            <velocity>100</velocity>
            <lower>-1e+16</lower>
            <upper>1e+16</upper>
          </limit>
          <dynamics>
            <spring_reference>0</spring_reference>
            <spring_stiffness>0</spring_stiffness>
          </dynamics>
        </axis>
      </joint>
      <link name='first_wheel_link'>
        <pose relative_to='first_wheel_joint'>0 0 0 0 -0 0</pose>
        <inertial>
          <pose>0 -0.011 0 0 -0 0</pose>
          <mass>0.25</mass>
          <inertia>
            <ixx>0.00031</ixx>
            <ixy>0</ixy>
            <ixz>0</ixz>
            <iyy>0.0005</iyy>
            <iyz>0</iyz>
            <izz>0.00031</izz>
          </inertia>
        </inertial>
        <collision name='first_wheel_link_collision'>
          <pose>0 0 0 0 -0 0</pose>
          <geometry>
            <mesh>
              <scale>1 1 1</scale>
              <uri>/home/yp7/catkin_ws/src/Omni_wheel_robot_GazeboSim/omni_robot_description/meshes/STL/omni_wheel/omni_wheel.stl</uri>
            </mesh>
          </geometry>
          <surface>
            <contact>
              <ode/>
            </contact>
            <friction>
              <ode>
                <mu>0.8</mu>
                <mu2>0.8</mu2>
              </ode>
              <torsional>
                <ode/>
              </torsional>
            </friction>
            <bounce/>
          </surface>
          <max_contacts>10</max_contacts>
        </collision>
        <visual name='first_wheel_link_visual'>
          <pose>0 0 0 0 -0 0</pose>
          <geometry>
            <mesh>
              <scale>1 1 1</scale>
              <uri>/home/yp7/catkin_ws/src/Omni_wheel_robot_GazeboSim/omni_robot_description/meshes/DAE/omni_wheel/omni_wheel.dae</uri>
            </mesh>
          </geometry>
        </visual>
        <self_collide>0</self_collide>
        <enable_wind>0</enable_wind>
        <kinematic>0</kinematic>
      </link>
      <joint name='r10_F_roller_joint' type='revolute'>
        <pose relative_to='first_wheel_link'>-0.022885 0.006 -0.007436 1.25664 -0 1.5708</pose>
        <parent>first_wheel_link</parent>
        <child>r10_F_roller_link</child>
        <axis>
          <xyz>0 1 0</xyz>
          <limit>
            <lower>-1e+16</lower>
            <upper>1e+16</upper>
          </limit>
          <dynamics>
            <spring_reference>0</spring_reference>
            <spring_stiffness>0</spring_stiffness>
          </dynamics>
        </axis>
      </joint>
      <link name='r10_F_roller_link'>
        <pose relative_to='r10_F_roller_joint'>0 0 0 0 -0 0</pose>
        <inertial>
          <pose>0 0 0 0 -0 0</pose>
          <mass>0.009</mass>
          <inertia>
            <ixx>1.257e-06</ixx>
            <ixy>0</ixy>
            <ixz>0</ixz>
            <iyy>3.42e-07</iyy>
            <iyz>0</iyz>
            <izz>1.257e-06</izz>
          </inertia>
        </inertial>
        <collision name='r10_F_roller_link_collision'>
          <pose>0 0 0 0 -0 0</pose>
          <geometry>
            <mesh>
              <scale>1 1 1</scale>
              <uri>/home/yp7/catkin_ws/src/Omni_wheel_robot_GazeboSim/omni_robot_description/meshes/STL/roller/roller.stl</uri>
            </mesh>
          </geometry>
          <max_contacts>10</max_contacts>
          <surface>
            <contact>
              <ode/>
            </contact>
            <bounce/>
            <friction>
              <torsional>
                <ode/>
              </torsional>
              <ode/>
            </friction>
          </surface>
        </collision>
        <visual name='r10_F_roller_link_visual'>
          <pose>0 0 0 0 -0 0</pose>
          <geometry>
            <mesh>
              <scale>1 1 1</scale>
              <uri>/home/yp7/catkin_ws/src/Omni_wheel_robot_GazeboSim/omni_robot_description/meshes/DAE/roller/omni_roller.dae</uri>
            </mesh>
          </geometry>
        </visual>
        <self_collide>0</self_collide>
        <enable_wind>0</enable_wind>
        <kinematic>0</kinematic>
      </link>
      <joint name='r1_F_roller_joint' type='revolute'>
        <pose relative_to='first_wheel_link'>0 -0.006 0.024063 0 -0 1.5708</pose>
        <parent>first_wheel_link</parent>
        <child>r1_F_roller_link</child>
        <axis>
          <xyz>0 1 0</xyz>
          <limit>
            <lower>-1e+16</lower>
            <upper>1e+16</upper>
          </limit>
          <dynamics>
            <spring_reference>0</spring_reference>
            <spring_stiffness>0</spring_stiffness>
          </dynamics>
        </axis>
      </joint>
      <link name='r1_F_roller_link'>
        <pose relative_to='r1_F_roller_joint'>0 0 0 0 -0 0</pose>
        <inertial>
          <pose>0 0 0 0 -0 0</pose>
          <mass>0.009</mass>
          <inertia>
            <ixx>1.257e-06</ixx>
            <ixy>0</ixy>
            <ixz>0</ixz>
            <iyy>3.42e-07</iyy>
            <iyz>0</iyz>
            <izz>1.257e-06</izz>
          </inertia>
        </inertial>
        <collision name='r1_F_roller_link_collision'>
          <pose>0 0 0 0 -0 0</pose>
          <geometry>
            <mesh>
              <scale>1 1 1</scale>
              <uri>/home/yp7/catkin_ws/src/Omni_wheel_robot_GazeboSim/omni_robot_description/meshes/STL/roller/roller.stl</uri>
            </mesh>
          </geometry>
          <max_contacts>10</max_contacts>
          <surface>
            <contact>
              <ode/>
            </contact>
            <bounce/>
            <friction>
              <torsional>
                <ode/>
              </torsional>
              <ode/>
            </friction>
          </surface>
        </collision>
        <visual name='r1_F_roller_link_visual'>
          <pose>0 0 0 0 -0 0</pose>
          <geometry>
            <mesh>
              <scale>1 1 1</scale>
              <uri>/home/yp7/catkin_ws/src/Omni_wheel_robot_GazeboSim/omni_robot_description/meshes/DAE/roller/omni_roller.dae</uri>
            </mesh>
          </geometry>
        </visual>
        <self_collide>0</self_collide>
        <enable_wind>0</enable_wind>
        <kinematic>0</kinematic>
      </link>
      <joint name='r2_F_roller_joint' type='revolute'>
        <pose relative_to='first_wheel_link'>-0.022885 -0.006 0.007436 -1.25664 0 1.5708</pose>
        <parent>first_wheel_link</parent>
        <child>r2_F_roller_link</child>
        <axis>
          <xyz>0 1 0</xyz>
          <limit>
            <lower>-1e+16</lower>
            <upper>1e+16</upper>
          </limit>
          <dynamics>
            <spring_reference>0</spring_reference>
            <spring_stiffness>0</spring_stiffness>
          </dynamics>
        </axis>
      </joint>
      <link name='r2_F_roller_link'>
        <pose relative_to='r2_F_roller_joint'>0 0 0 0 -0 0</pose>
        <inertial>
          <pose>0 0 0 0 -0 0</pose>
          <mass>0.009</mass>
          <inertia>
            <ixx>1.257e-06</ixx>
            <ixy>0</ixy>
            <ixz>0</ixz>
            <iyy>3.42e-07</iyy>
            <iyz>0</iyz>
            <izz>1.257e-06</izz>
          </inertia>
        </inertial>
        <collision name='r2_F_roller_link_collision'>
          <pose>0 0 0 0 -0 0</pose>
          <geometry>
            <mesh>
              <scale>1 1 1</scale>
              <uri>/home/yp7/catkin_ws/src/Omni_wheel_robot_GazeboSim/omni_robot_description/meshes/STL/roller/roller.stl</uri>
            </mesh>
          </geometry>
          <max_contacts>10</max_contacts>
          <surface>
            <contact>
              <ode/>
            </contact>
            <bounce/>
            <friction>
              <torsional>
                <ode/>
              </torsional>
              <ode/>
            </friction>
          </surface>
        </collision>
        <visual name='r2_F_roller_link_visual'>
          <pose>0 0 0 0 -0 0</pose>
          <geometry>
            <mesh>
              <scale>1 1 1</scale>
              <uri>/home/yp7/catkin_ws/src/Omni_wheel_robot_GazeboSim/omni_robot_description/meshes/DAE/roller/omni_roller.dae</uri>
            </mesh>
          </geometry>
        </visual>
        <self_collide>0</self_collide>
        <enable_wind>0</enable_wind>
        <kinematic>0</kinematic>
      </link>
      <joint name='r3_F_roller_joint' type='revolute'>
        <pose relative_to='first_wheel_link'>-0.014144 -0.006 -0.019467 -2.51327 -0 1.5708</pose>
        <parent>first_wheel_link</parent>
        <child>r3_F_roller_link</child>
        <axis>
          <xyz>0 1 0</xyz>
          <limit>
            <lower>-1e+16</lower>
            <upper>1e+16</upper>
          </limit>
          <dynamics>
            <spring_reference>0</spring_reference>
            <spring_stiffness>0</spring_stiffness>
          </dynamics>
        </axis>
      </joint>
      <link name='r3_F_roller_link'>
        <pose relative_to='r3_F_roller_joint'>0 0 0 0 -0 0</pose>
        <inertial>
          <pose>0 0 0 0 -0 0</pose>
          <mass>0.009</mass>
          <inertia>
            <ixx>1.257e-06</ixx>
            <ixy>0</ixy>
            <ixz>0</ixz>
            <iyy>3.42e-07</iyy>
            <iyz>0</iyz>
            <izz>1.257e-06</izz>
          </inertia>
        </inertial>
        <collision name='r3_F_roller_link_collision'>
          <pose>0 0 0 0 -0 0</pose>
          <geometry>
            <mesh>
              <scale>1 1 1</scale>
              <uri>/home/yp7/catkin_ws/src/Omni_wheel_robot_GazeboSim/omni_robot_description/meshes/STL/roller/roller.stl</uri>
            </mesh>
          </geometry>
          <max_contacts>10</max_contacts>
          <surface>
            <contact>
              <ode/>
            </contact>
            <bounce/>
            <friction>
              <torsional>
                <ode/>
              </torsional>
              <ode/>
            </friction>
          </surface>
        </collision>
        <visual name='r3_F_roller_link_visual'>
          <pose>0 0 0 0 -0 0</pose>
          <geometry>
            <mesh>
              <scale>1 1 1</scale>
              <uri>/home/yp7/catkin_ws/src/Omni_wheel_robot_GazeboSim/omni_robot_description/meshes/DAE/roller/omni_roller.dae</uri>
            </mesh>
          </geometry>
        </visual>
        <self_collide>0</self_collide>
        <enable_wind>0</enable_wind>
        <kinematic>0</kinematic>
      </link>
      <joint name='r4_F_roller_joint' type='revolute'>
        <pose relative_to='first_wheel_link'>0.014144 -0.006 -0.019467 2.51327 -0 1.5708</pose>
        <parent>first_wheel_link</parent>
        <child>r4_F_roller_link</child>
        <axis>
          <xyz>0 1 0</xyz>
          <limit>
            <lower>-1e+16</lower>
            <upper>1e+16</upper>
          </limit>
          <dynamics>
            <spring_reference>0</spring_reference>
            <spring_stiffness>0</spring_stiffness>
          </dynamics>
        </axis>
      </joint>
      <link name='r4_F_roller_link'>
        <pose relative_to='r4_F_roller_joint'>0 0 0 0 -0 0</pose>
        <inertial>
          <pose>0 0 0 0 -0 0</pose>
          <mass>0.009</mass>
          <inertia>
            <ixx>1.257e-06</ixx>
            <ixy>0</ixy>
            <ixz>0</ixz>
            <iyy>3.42e-07</iyy>
            <iyz>0</iyz>
            <izz>1.257e-06</izz>
          </inertia>
        </inertial>
        <collision name='r4_F_roller_link_collision'>
          <pose>0 0 0 0 -0 0</pose>
          <geometry>
            <mesh>
              <scale>1 1 1</scale>
              <uri>/home/yp7/catkin_ws/src/Omni_wheel_robot_GazeboSim/omni_robot_description/meshes/STL/roller/roller.stl</uri>
            </mesh>
          </geometry>
          <max_contacts>10</max_contacts>
          <surface>
            <contact>
              <ode/>
            </contact>
            <bounce/>
            <friction>
              <torsional>
                <ode/>
              </torsional>
              <ode/>
            </friction>
          </surface>
        </collision>
        <visual name='r4_F_roller_link_visual'>
          <pose>0 0 0 0 -0 0</pose>
          <geometry>
            <mesh>
              <scale>1 1 1</scale>
              <uri>/home/yp7/catkin_ws/src/Omni_wheel_robot_GazeboSim/omni_robot_description/meshes/DAE/roller/omni_roller.dae</uri>
            </mesh>
          </geometry>
        </visual>
        <self_collide>0</self_collide>
        <enable_wind>0</enable_wind>
        <kinematic>0</kinematic>
      </link>
      <joint name='r5_F_roller_joint' type='revolute'>
        <pose relative_to='first_wheel_link'>0.022885 -0.006 0.007436 1.25664 -0 1.5708</pose>
        <parent>first_wheel_link</parent>
        <child>r5_F_roller_link</child>
        <axis>
          <xyz>0 1 0</xyz>
          <limit>
            <lower>-1e+16</lower>
            <upper>1e+16</upper>
          </limit>
          <dynamics>
            <spring_reference>0</spring_reference>
            <spring_stiffness>0</spring_stiffness>
          </dynamics>
        </axis>
      </joint>
      <link name='r5_F_roller_link'>
        <pose relative_to='r5_F_roller_joint'>0 0 0 0 -0 0</pose>
        <inertial>
          <pose>0 0 0 0 -0 0</pose>
          <mass>0.009</mass>
          <inertia>
            <ixx>1.257e-06</ixx>
            <ixy>0</ixy>
            <ixz>0</ixz>
            <iyy>3.42e-07</iyy>
            <iyz>0</iyz>
            <izz>1.257e-06</izz>
          </inertia>
        </inertial>
        <collision name='r5_F_roller_link_collision'>
          <pose>0 0 0 0 -0 0</pose>
          <geometry>
            <mesh>
              <scale>1 1 1</scale>
              <uri>/home/yp7/catkin_ws/src/Omni_wheel_robot_GazeboSim/omni_robot_description/meshes/STL/roller/roller.stl</uri>
            </mesh>
          </geometry>
          <max_contacts>10</max_contacts>
          <surface>
            <contact>
              <ode/>
            </contact>
            <bounce/>
            <friction>
              <torsional>
                <ode/>
              </torsional>
              <ode/>
            </friction>
          </surface>
        </collision>
        <visual name='r5_F_roller_link_visual'>
          <pose>0 0 0 0 -0 0</pose>
          <geometry>
            <mesh>
              <scale>1 1 1</scale>
              <uri>/home/yp7/catkin_ws/src/Omni_wheel_robot_GazeboSim/omni_robot_description/meshes/DAE/roller/omni_roller.dae</uri>
            </mesh>
          </geometry>
        </visual>
        <self_collide>0</self_collide>
        <enable_wind>0</enable_wind>
        <kinematic>0</kinematic>
      </link>
      <joint name='r6_F_roller_joint' type='revolute'>
        <pose relative_to='first_wheel_link'>0 0.006 -0.024063 0 -0 1.5708</pose>
        <parent>first_wheel_link</parent>
        <child>r6_F_roller_link</child>
        <axis>
          <xyz>0 1 0</xyz>
          <limit>
            <lower>-1e+16</lower>
            <upper>1e+16</upper>
          </limit>
          <dynamics>
            <spring_reference>0</spring_reference>
            <spring_stiffness>0</spring_stiffness>
          </dynamics>
        </axis>
      </joint>
      <link name='r6_F_roller_link'>
        <pose relative_to='r6_F_roller_joint'>0 0 0 0 -0 0</pose>
        <inertial>
          <pose>0 0 0 0 -0 0</pose>
          <mass>0.009</mass>
          <inertia>
            <ixx>1.257e-06</ixx>
            <ixy>0</ixy>
            <ixz>0</ixz>
            <iyy>3.42e-07</iyy>
            <iyz>0</iyz>
            <izz>1.257e-06</izz>
          </inertia>
        </inertial>
        <collision name='r6_F_roller_link_collision'>
          <pose>0 0 0 0 -0 0</pose>
          <geometry>
            <mesh>
              <scale>1 1 1</scale>
              <uri>/home/yp7/catkin_ws/src/Omni_wheel_robot_GazeboSim/omni_robot_description/meshes/STL/roller/roller.stl</uri>
            </mesh>
          </geometry>
          <max_contacts>10</max_contacts>
          <surface>
            <contact>
              <ode/>
            </contact>
            <bounce/>
            <friction>
              <torsional>
                <ode/>
              </torsional>
              <ode/>
            </friction>
          </surface>
        </collision>
        <visual name='r6_F_roller_link_visual'>
          <pose>0 0 0 0 -0 0</pose>
          <geometry>
            <mesh>
              <scale>1 1 1</scale>
              <uri>/home/yp7/catkin_ws/src/Omni_wheel_robot_GazeboSim/omni_robot_description/meshes/DAE/roller/omni_roller.dae</uri>
            </mesh>
          </geometry>
        </visual>
        <self_collide>0</self_collide>
        <enable_wind>0</enable_wind>
        <kinematic>0</kinematic>
      </link>
      <joint name='r7_F_roller_joint' type='revolute'>
        <pose relative_to='first_wheel_link'>0.022885 0.006 -0.007436 -1.25664 0 1.5708</pose>
        <parent>first_wheel_link</parent>
        <child>r7_F_roller_link</child>
        <axis>
          <xyz>0 1 0</xyz>
          <limit>
            <lower>-1e+16</lower>
            <upper>1e+16</upper>
          </limit>
          <dynamics>
            <spring_reference>0</spring_reference>
            <spring_stiffness>0</spring_stiffness>
          </dynamics>
        </axis>
      </joint>
      <link name='r7_F_roller_link'>
        <pose relative_to='r7_F_roller_joint'>0 0 0 0 -0 0</pose>
        <inertial>
          <pose>0 0 0 0 -0 0</pose>
          <mass>0.009</mass>
          <inertia>
            <ixx>1.257e-06</ixx>
            <ixy>0</ixy>
            <ixz>0</ixz>
            <iyy>3.42e-07</iyy>
            <iyz>0</iyz>
            <izz>1.257e-06</izz>
          </inertia>
        </inertial>
        <collision name='r7_F_roller_link_collision'>
          <pose>0 0 0 0 -0 0</pose>
          <geometry>
            <mesh>
              <scale>1 1 1</scale>
              <uri>/home/yp7/catkin_ws/src/Omni_wheel_robot_GazeboSim/omni_robot_description/meshes/STL/roller/roller.stl</uri>
            </mesh>
          </geometry>
          <max_contacts>10</max_contacts>
          <surface>
            <contact>
              <ode/>
            </contact>
            <bounce/>
            <friction>
              <torsional>
                <ode/>
              </torsional>
              <ode/>
            </friction>
          </surface>
        </collision>
        <visual name='r7_F_roller_link_visual'>
          <pose>0 0 0 0 -0 0</pose>
          <geometry>
            <mesh>
              <scale>1 1 1</scale>
              <uri>/home/yp7/catkin_ws/src/Omni_wheel_robot_GazeboSim/omni_robot_description/meshes/DAE/roller/omni_roller.dae</uri>
            </mesh>
          </geometry>
        </visual>
        <self_collide>0</self_collide>
        <enable_wind>0</enable_wind>
        <kinematic>0</kinematic>
      </link>
      <joint name='r8_F_roller_joint' type='revolute'>
        <pose relative_to='first_wheel_link'>0.014144 0.006 0.019467 -2.51327 -0 1.5708</pose>
        <parent>first_wheel_link</parent>
        <child>r8_F_roller_link</child>
        <axis>
          <xyz>0 1 0</xyz>
          <limit>
            <lower>-1e+16</lower>
            <upper>1e+16</upper>
          </limit>
          <dynamics>
            <spring_reference>0</spring_reference>
            <spring_stiffness>0</spring_stiffness>
          </dynamics>
        </axis>
      </joint>
      <link name='r8_F_roller_link'>
        <pose relative_to='r8_F_roller_joint'>0 0 0 0 -0 0</pose>
        <inertial>
          <pose>0 0 0 0 -0 0</pose>
          <mass>0.009</mass>
          <inertia>
            <ixx>1.257e-06</ixx>
            <ixy>0</ixy>
            <ixz>0</ixz>
            <iyy>3.42e-07</iyy>
            <iyz>0</iyz>
            <izz>1.257e-06</izz>
          </inertia>
        </inertial>
        <collision name='r8_F_roller_link_collision'>
          <pose>0 0 0 0 -0 0</pose>
          <geometry>
            <mesh>
              <scale>1 1 1</scale>
              <uri>/home/yp7/catkin_ws/src/Omni_wheel_robot_GazeboSim/omni_robot_description/meshes/STL/roller/roller.stl</uri>
            </mesh>
          </geometry>
          <max_contacts>10</max_contacts>
          <surface>
            <contact>
              <ode/>
            </contact>
            <bounce/>
            <friction>
              <torsional>
                <ode/>
              </torsional>
              <ode/>
            </friction>
          </surface>
        </collision>
        <visual name='r8_F_roller_link_visual'>
          <pose>0 0 0 0 -0 0</pose>
          <geometry>
            <mesh>
              <scale>1 1 1</scale>
              <uri>/home/yp7/catkin_ws/src/Omni_wheel_robot_GazeboSim/omni_robot_description/meshes/DAE/roller/omni_roller.dae</uri>
            </mesh>
          </geometry>
        </visual>
        <self_collide>0</self_collide>
        <enable_wind>0</enable_wind>
        <kinematic>0</kinematic>
      </link>
      <joint name='r9_F_roller_joint' type='revolute'>
        <pose relative_to='first_wheel_link'>-0.014144 0.006 0.019467 2.51327 -0 1.5708</pose>
        <parent>first_wheel_link</parent>
        <child>r9_F_roller_link</child>
        <axis>
          <xyz>0 1 0</xyz>
          <limit>
            <lower>-1e+16</lower>
            <upper>1e+16</upper>
          </limit>
          <dynamics>
            <spring_reference>0</spring_reference>
            <spring_stiffness>0</spring_stiffness>
          </dynamics>
        </axis>
      </joint>
      <link name='r9_F_roller_link'>
        <pose relative_to='r9_F_roller_joint'>0 0 0 0 -0 0</pose>
        <inertial>
          <pose>0 0 0 0 -0 0</pose>
          <mass>0.009</mass>
          <inertia>
            <ixx>1.257e-06</ixx>
            <ixy>0</ixy>
            <ixz>0</ixz>
            <iyy>3.42e-07</iyy>
            <iyz>0</iyz>
            <izz>1.257e-06</izz>
          </inertia>
        </inertial>
        <collision name='r9_F_roller_link_collision'>
          <pose>0 0 0 0 -0 0</pose>
          <geometry>
            <mesh>
              <scale>1 1 1</scale>
              <uri>/home/yp7/catkin_ws/src/Omni_wheel_robot_GazeboSim/omni_robot_description/meshes/STL/roller/roller.stl</uri>
            </mesh>
          </geometry>
          <max_contacts>10</max_contacts>
          <surface>
            <contact>
              <ode/>
            </contact>
            <bounce/>
            <friction>
              <torsional>
                <ode/>
              </torsional>
              <ode/>
            </friction>
          </surface>
        </collision>
        <visual name='r9_F_roller_link_visual'>
          <pose>0 0 0 0 -0 0</pose>
          <geometry>
            <mesh>
              <scale>1 1 1</scale>
              <uri>/home/yp7/catkin_ws/src/Omni_wheel_robot_GazeboSim/omni_robot_description/meshes/DAE/roller/omni_roller.dae</uri>
            </mesh>
          </geometry>
        </visual>
        <self_collide>0</self_collide>
        <enable_wind>0</enable_wind>
        <kinematic>0</kinematic>
      </link>
      <joint name='main_camera_bracket_joint' type='revolute'>
        <pose relative_to='base_footprint'>0 0 0.039 0 -0 1.5708</pose>
        <parent>base_footprint</parent>
        <child>main_camera_bracket_link</child>
        <axis>
          <xyz>0 0 1</xyz>
          <limit>
            <lower>-1e+16</lower>
            <upper>1e+16</upper>
          </limit>
          <dynamics>
            <spring_reference>0</spring_reference>
            <spring_stiffness>0</spring_stiffness>
          </dynamics>
        </axis>
      </joint>
      <link name='main_camera_bracket_link'>
        <pose relative_to='main_camera_bracket_joint'>0 0 0 0 -0 0</pose>
        <inertial>
          <pose>0 0 0.055455 0 -0 0</pose>
          <mass>0.11</mass>
          <inertia>
            <ixx>0.000353827</ixx>
            <ixy>0</ixy>
            <ixz>0</ixz>
            <iyy>0.000543827</iyy>
            <iyz>0</iyz>
            <izz>0.00032</izz>
          </inertia>
        </inertial>
        <collision name='main_camera_bracket_link_collision'>
          <pose>0 0 0 0 -0 0</pose>
          <geometry>
            <mesh>
              <scale>1 1 1</scale>
              <uri>/home/yp7/catkin_ws/src/Omni_wheel_robot_GazeboSim/omni_robot_description/meshes/STL/camera_bracket/camera_bracket.stl</uri>
            </mesh>
          </geometry>
          <surface>
            <contact>
              <ode/>
            </contact>
            <friction>
              <ode>
                <mu>0.2</mu>
                <mu2>0.2</mu2>
              </ode>
              <torsional>
                <ode/>
              </torsional>
            </friction>
            <bounce/>
          </surface>
          <max_contacts>10</max_contacts>
        </collision>
        <collision name='main_camera_bracket_link_fixed_joint_lump__main_camera_link_collision_1'>
          <pose>0 0 0.061 0 0.5236 0</pose>
          <geometry>
            <mesh>
              <scale>1 1 1</scale>
              <uri>/home/yp7/catkin_ws/src/Omni_wheel_robot_GazeboSim/omni_robot_description/meshes/STL/camera/camera.stl</uri>
            </mesh>
          </geometry>
          <surface>
            <contact>
              <ode/>
            </contact>
            <friction>
              <ode/>
              <torsional>
                <ode/>
              </torsional>
            </friction>
            <bounce/>
          </surface>
          <max_contacts>10</max_contacts>
        </collision>
        <visual name='main_camera_bracket_link_visual'>
          <pose>0 0 0 0 -0 0</pose>
          <geometry>
            <mesh>
              <scale>1 1 1</scale>
              <uri>/home/yp7/catkin_ws/src/Omni_wheel_robot_GazeboSim/omni_robot_description/meshes/DAE/camera_bracket/camera_bracket.dae</uri>
            </mesh>
          </geometry>
        </visual>
        <visual name='main_camera_bracket_link_fixed_joint_lump__main_camera_link_visual_1'>
          <pose>0 0 0.061 0 0.5236 0</pose>
          <geometry>
            <mesh>
              <scale>1 1 1</scale>
              <uri>/home/yp7/catkin_ws/src/Omni_wheel_robot_GazeboSim/omni_robot_description/meshes/DAE/camera/camera.dae</uri>
            </mesh>
          </geometry>
        </visual>
        <self_collide>0</self_collide>
        <sensor name='main' type='camera'>
          <update_rate>10</update_rate>
          <camera name='main_camera'>
            <pose>0 0 0 0 -0 0</pose>
            <horizontal_fov>1.39626</horizontal_fov>
            <image>
              <width>640</width>
              <height>480</height>
              <format>R8G8B8</format>
            </image>
            <clip>
              <near>0.02</near>
              <far>300</far>
            </clip>
            <noise>
              <type>gaussian</type>
              <mean>0</mean>
              <stddev>0.007</stddev>
            </noise>
          </camera>
          <plugin name='camera_controller' filename='libgazebo_ros_camera.so'>
            <alwaysOn>1</alwaysOn>
            <updateRate>0.0</updateRate>
            <cameraName>main_camera</cameraName>
            <imageTopicName>image_raw</imageTopicName>
            <cameraInfoTopicName>camera_info</cameraInfoTopicName>
            <frameName>main_link</frameName>
            <hackBaseline>0.0</hackBaseline>
            <distortionK1>0.0</distortionK1>
            <distortionK2>0.0</distortionK2>
            <distortionK3>0.0</distortionK3>
            <distortionT1>0.0</distortionT1>
            <distortionT2>0.0</distortionT2>
            <robotNamespace>/robot_omni/</robotNamespace>
          </plugin>
          <pose>0 0 0.061 0 0.5236 0</pose>
        </sensor>
        <enable_wind>0</enable_wind>
        <kinematic>0</kinematic>
      </link>
      <joint name='second_wheel_joint' type='revolute'>
        <pose relative_to='base_footprint'>-0.0762 -0.044 -0.01 0 0 -1.0472</pose>
        <parent>base_footprint</parent>
        <child>second_wheel_link</child>
        <axis>
          <xyz>0 1 0</xyz>
          <limit>
            <effort>100</effort>
            <velocity>100</velocity>
            <lower>-1e+16</lower>
            <upper>1e+16</upper>
          </limit>
          <dynamics>
            <spring_reference>0</spring_reference>
            <spring_stiffness>0</spring_stiffness>
          </dynamics>
        </axis>
      </joint>
      <link name='second_wheel_link'>
        <pose relative_to='second_wheel_joint'>0 0 0 0 -0 0</pose>
        <inertial>
          <pose>0 -0.011 0 0 -0 0</pose>
          <mass>0.25</mass>
          <inertia>
            <ixx>0.00031</ixx>
            <ixy>0</ixy>
            <ixz>0</ixz>
            <iyy>0.0005</iyy>
            <iyz>0</iyz>
            <izz>0.00031</izz>
          </inertia>
        </inertial>
        <collision name='second_wheel_link_collision'>
          <pose>0 0 0 0 -0 0</pose>
          <geometry>
            <mesh>
              <scale>1 1 1</scale>
              <uri>/home/yp7/catkin_ws/src/Omni_wheel_robot_GazeboSim/omni_robot_description/meshes/STL/omni_wheel/omni_wheel.stl</uri>
            </mesh>
          </geometry>
          <surface>
            <contact>
              <ode/>
            </contact>
            <friction>
              <ode>
                <mu>0.8</mu>
                <mu2>0.8</mu2>
              </ode>
              <torsional>
                <ode/>
              </torsional>
            </friction>
            <bounce/>
          </surface>
          <max_contacts>10</max_contacts>
        </collision>
        <visual name='second_wheel_link_visual'>
          <pose>0 0 0 0 -0 0</pose>
          <geometry>
            <mesh>
              <scale>1 1 1</scale>
              <uri>/home/yp7/catkin_ws/src/Omni_wheel_robot_GazeboSim/omni_robot_description/meshes/DAE/omni_wheel/omni_wheel.dae</uri>
            </mesh>
          </geometry>
        </visual>
        <self_collide>0</self_collide>
        <enable_wind>0</enable_wind>
        <kinematic>0</kinematic>
      </link>
      <joint name='r10_S_roller_joint' type='revolute'>
        <pose relative_to='second_wheel_link'>-0.022885 0.006 -0.007436 1.25664 -0 1.5708</pose>
        <parent>second_wheel_link</parent>
        <child>r10_S_roller_link</child>
        <axis>
          <xyz>0 1 0</xyz>
          <limit>
            <lower>-1e+16</lower>
            <upper>1e+16</upper>
          </limit>
          <dynamics>
            <spring_reference>0</spring_reference>
            <spring_stiffness>0</spring_stiffness>
          </dynamics>
        </axis>
      </joint>
      <link name='r10_S_roller_link'>
        <pose relative_to='r10_S_roller_joint'>0 0 0 0 -0 0</pose>
        <inertial>
          <pose>0 0 0 0 -0 0</pose>
          <mass>0.009</mass>
          <inertia>
            <ixx>1.257e-06</ixx>
            <ixy>0</ixy>
            <ixz>0</ixz>
            <iyy>3.42e-07</iyy>
            <iyz>0</iyz>
            <izz>1.257e-06</izz>
          </inertia>
        </inertial>
        <collision name='r10_S_roller_link_collision'>
          <pose>0 0 0 0 -0 0</pose>
          <geometry>
            <mesh>
              <scale>1 1 1</scale>
              <uri>/home/yp7/catkin_ws/src/Omni_wheel_robot_GazeboSim/omni_robot_description/meshes/STL/roller/roller.stl</uri>
            </mesh>
          </geometry>
          <max_contacts>10</max_contacts>
          <surface>
            <contact>
              <ode/>
            </contact>
            <bounce/>
            <friction>
              <torsional>
                <ode/>
              </torsional>
              <ode/>
            </friction>
          </surface>
        </collision>
        <visual name='r10_S_roller_link_visual'>
          <pose>0 0 0 0 -0 0</pose>
          <geometry>
            <mesh>
              <scale>1 1 1</scale>
              <uri>/home/yp7/catkin_ws/src/Omni_wheel_robot_GazeboSim/omni_robot_description/meshes/DAE/roller/omni_roller.dae</uri>
            </mesh>
          </geometry>
        </visual>
        <self_collide>0</self_collide>
        <enable_wind>0</enable_wind>
        <kinematic>0</kinematic>
      </link>
      <joint name='r1_S_roller_joint' type='revolute'>
        <pose relative_to='second_wheel_link'>0 -0.006 0.024063 0 -0 1.5708</pose>
        <parent>second_wheel_link</parent>
        <child>r1_S_roller_link</child>
        <axis>
          <xyz>0 1 0</xyz>
          <limit>
            <lower>-1e+16</lower>
            <upper>1e+16</upper>
          </limit>
          <dynamics>
            <spring_reference>0</spring_reference>
            <spring_stiffness>0</spring_stiffness>
          </dynamics>
        </axis>
      </joint>
      <link name='r1_S_roller_link'>
        <pose relative_to='r1_S_roller_joint'>0 0 0 0 -0 0</pose>
        <inertial>
          <pose>0 0 0 0 -0 0</pose>
          <mass>0.009</mass>
          <inertia>
            <ixx>1.257e-06</ixx>
            <ixy>0</ixy>
            <ixz>0</ixz>
            <iyy>3.42e-07</iyy>
            <iyz>0</iyz>
            <izz>1.257e-06</izz>
          </inertia>
        </inertial>
        <collision name='r1_S_roller_link_collision'>
          <pose>0 0 0 0 -0 0</pose>
          <geometry>
            <mesh>
              <scale>1 1 1</scale>
              <uri>/home/yp7/catkin_ws/src/Omni_wheel_robot_GazeboSim/omni_robot_description/meshes/STL/roller/roller.stl</uri>
            </mesh>
          </geometry>
          <max_contacts>10</max_contacts>
          <surface>
            <contact>
              <ode/>
            </contact>
            <bounce/>
            <friction>
              <torsional>
                <ode/>
              </torsional>
              <ode/>
            </friction>
          </surface>
        </collision>
        <visual name='r1_S_roller_link_visual'>
          <pose>0 0 0 0 -0 0</pose>
          <geometry>
            <mesh>
              <scale>1 1 1</scale>
              <uri>/home/yp7/catkin_ws/src/Omni_wheel_robot_GazeboSim/omni_robot_description/meshes/DAE/roller/omni_roller.dae</uri>
            </mesh>
          </geometry>
        </visual>
        <self_collide>0</self_collide>
        <enable_wind>0</enable_wind>
        <kinematic>0</kinematic>
      </link>
      <joint name='r2_S_roller_joint' type='revolute'>
        <pose relative_to='second_wheel_link'>-0.022885 -0.006 0.007436 -1.25664 0 1.5708</pose>
        <parent>second_wheel_link</parent>
        <child>r2_S_roller_link</child>
        <axis>
          <xyz>0 1 0</xyz>
          <limit>
            <lower>-1e+16</lower>
            <upper>1e+16</upper>
          </limit>
          <dynamics>
            <spring_reference>0</spring_reference>
            <spring_stiffness>0</spring_stiffness>
          </dynamics>
        </axis>
      </joint>
      <link name='r2_S_roller_link'>
        <pose relative_to='r2_S_roller_joint'>0 0 0 0 -0 0</pose>
        <inertial>
          <pose>0 0 0 0 -0 0</pose>
          <mass>0.009</mass>
          <inertia>
            <ixx>1.257e-06</ixx>
            <ixy>0</ixy>
            <ixz>0</ixz>
            <iyy>3.42e-07</iyy>
            <iyz>0</iyz>
            <izz>1.257e-06</izz>
          </inertia>
        </inertial>
        <collision name='r2_S_roller_link_collision'>
          <pose>0 0 0 0 -0 0</pose>
          <geometry>
            <mesh>
              <scale>1 1 1</scale>
              <uri>/home/yp7/catkin_ws/src/Omni_wheel_robot_GazeboSim/omni_robot_description/meshes/STL/roller/roller.stl</uri>
            </mesh>
          </geometry>
          <max_contacts>10</max_contacts>
          <surface>
            <contact>
              <ode/>
            </contact>
            <bounce/>
            <friction>
              <torsional>
                <ode/>
              </torsional>
              <ode/>
            </friction>
          </surface>
        </collision>
        <visual name='r2_S_roller_link_visual'>
          <pose>0 0 0 0 -0 0</pose>
          <geometry>
            <mesh>
              <scale>1 1 1</scale>
              <uri>/home/yp7/catkin_ws/src/Omni_wheel_robot_GazeboSim/omni_robot_description/meshes/DAE/roller/omni_roller.dae</uri>
            </mesh>
          </geometry>
        </visual>
        <self_collide>0</self_collide>
        <enable_wind>0</enable_wind>
        <kinematic>0</kinematic>
      </link>
      <joint name='r3_S_roller_joint' type='revolute'>
        <pose relative_to='second_wheel_link'>-0.014144 -0.006 -0.019467 -2.51327 -0 1.5708</pose>
        <parent>second_wheel_link</parent>
        <child>r3_S_roller_link</child>
        <axis>
          <xyz>0 1 0</xyz>
          <limit>
            <lower>-1e+16</lower>
            <upper>1e+16</upper>
          </limit>
          <dynamics>
            <spring_reference>0</spring_reference>
            <spring_stiffness>0</spring_stiffness>
          </dynamics>
        </axis>
      </joint>
      <link name='r3_S_roller_link'>
        <pose relative_to='r3_S_roller_joint'>0 0 0 0 -0 0</pose>
        <inertial>
          <pose>0 0 0 0 -0 0</pose>
          <mass>0.009</mass>
          <inertia>
            <ixx>1.257e-06</ixx>
            <ixy>0</ixy>
            <ixz>0</ixz>
            <iyy>3.42e-07</iyy>
            <iyz>0</iyz>
            <izz>1.257e-06</izz>
          </inertia>
        </inertial>
        <collision name='r3_S_roller_link_collision'>
          <pose>0 0 0 0 -0 0</pose>
          <geometry>
            <mesh>
              <scale>1 1 1</scale>
              <uri>/home/yp7/catkin_ws/src/Omni_wheel_robot_GazeboSim/omni_robot_description/meshes/STL/roller/roller.stl</uri>
            </mesh>
          </geometry>
          <max_contacts>10</max_contacts>
          <surface>
            <contact>
              <ode/>
            </contact>
            <bounce/>
            <friction>
              <torsional>
                <ode/>
              </torsional>
              <ode/>
            </friction>
          </surface>
        </collision>
        <visual name='r3_S_roller_link_visual'>
          <pose>0 0 0 0 -0 0</pose>
          <geometry>
            <mesh>
              <scale>1 1 1</scale>
              <uri>/home/yp7/catkin_ws/src/Omni_wheel_robot_GazeboSim/omni_robot_description/meshes/DAE/roller/omni_roller.dae</uri>
            </mesh>
          </geometry>
        </visual>
        <self_collide>0</self_collide>
        <enable_wind>0</enable_wind>
        <kinematic>0</kinematic>
      </link>
      <joint name='r4_S_roller_joint' type='revolute'>
        <pose relative_to='second_wheel_link'>0.014144 -0.006 -0.019467 2.51327 -0 1.5708</pose>
        <parent>second_wheel_link</parent>
        <child>r4_S_roller_link</child>
        <axis>
          <xyz>0 1 0</xyz>
          <limit>
            <lower>-1e+16</lower>
            <upper>1e+16</upper>
          </limit>
          <dynamics>
            <spring_reference>0</spring_reference>
            <spring_stiffness>0</spring_stiffness>
          </dynamics>
        </axis>
      </joint>
      <link name='r4_S_roller_link'>
        <pose relative_to='r4_S_roller_joint'>0 0 0 0 -0 0</pose>
        <inertial>
          <pose>0 0 0 0 -0 0</pose>
          <mass>0.009</mass>
          <inertia>
            <ixx>1.257e-06</ixx>
            <ixy>0</ixy>
            <ixz>0</ixz>
            <iyy>3.42e-07</iyy>
            <iyz>0</iyz>
            <izz>1.257e-06</izz>
          </inertia>
        </inertial>
        <collision name='r4_S_roller_link_collision'>
          <pose>0 0 0 0 -0 0</pose>
          <geometry>
            <mesh>
              <scale>1 1 1</scale>
              <uri>/home/yp7/catkin_ws/src/Omni_wheel_robot_GazeboSim/omni_robot_description/meshes/STL/roller/roller.stl</uri>
            </mesh>
          </geometry>
          <max_contacts>10</max_contacts>
          <surface>
            <contact>
              <ode/>
            </contact>
            <bounce/>
            <friction>
              <torsional>
                <ode/>
              </torsional>
              <ode/>
            </friction>
          </surface>
        </collision>
        <visual name='r4_S_roller_link_visual'>
          <pose>0 0 0 0 -0 0</pose>
          <geometry>
            <mesh>
              <scale>1 1 1</scale>
              <uri>/home/yp7/catkin_ws/src/Omni_wheel_robot_GazeboSim/omni_robot_description/meshes/DAE/roller/omni_roller.dae</uri>
            </mesh>
          </geometry>
        </visual>
        <self_collide>0</self_collide>
        <enable_wind>0</enable_wind>
        <kinematic>0</kinematic>
      </link>
      <joint name='r5_S_roller_joint' type='revolute'>
        <pose relative_to='second_wheel_link'>0.022885 -0.006 0.007436 1.25664 -0 1.5708</pose>
        <parent>second_wheel_link</parent>
        <child>r5_S_roller_link</child>
        <axis>
          <xyz>0 1 0</xyz>
          <limit>
            <lower>-1e+16</lower>
            <upper>1e+16</upper>
          </limit>
          <dynamics>
            <spring_reference>0</spring_reference>
            <spring_stiffness>0</spring_stiffness>
          </dynamics>
        </axis>
      </joint>
      <link name='r5_S_roller_link'>
        <pose relative_to='r5_S_roller_joint'>0 0 0 0 -0 0</pose>
        <inertial>
          <pose>0 0 0 0 -0 0</pose>
          <mass>0.009</mass>
          <inertia>
            <ixx>1.257e-06</ixx>
            <ixy>0</ixy>
            <ixz>0</ixz>
            <iyy>3.42e-07</iyy>
            <iyz>0</iyz>
            <izz>1.257e-06</izz>
          </inertia>
        </inertial>
        <collision name='r5_S_roller_link_collision'>
          <pose>0 0 0 0 -0 0</pose>
          <geometry>
            <mesh>
              <scale>1 1 1</scale>
              <uri>/home/yp7/catkin_ws/src/Omni_wheel_robot_GazeboSim/omni_robot_description/meshes/STL/roller/roller.stl</uri>
            </mesh>
          </geometry>
          <max_contacts>10</max_contacts>
          <surface>
            <contact>
              <ode/>
            </contact>
            <bounce/>
            <friction>
              <torsional>
                <ode/>
              </torsional>
              <ode/>
            </friction>
          </surface>
        </collision>
        <visual name='r5_S_roller_link_visual'>
          <pose>0 0 0 0 -0 0</pose>
          <geometry>
            <mesh>
              <scale>1 1 1</scale>
              <uri>/home/yp7/catkin_ws/src/Omni_wheel_robot_GazeboSim/omni_robot_description/meshes/DAE/roller/omni_roller.dae</uri>
            </mesh>
          </geometry>
        </visual>
        <self_collide>0</self_collide>
        <enable_wind>0</enable_wind>
        <kinematic>0</kinematic>
      </link>
      <joint name='r6_S_roller_joint' type='revolute'>
        <pose relative_to='second_wheel_link'>0 0.006 -0.024063 0 -0 1.5708</pose>
        <parent>second_wheel_link</parent>
        <child>r6_S_roller_link</child>
        <axis>
          <xyz>0 1 0</xyz>
          <limit>
            <lower>-1e+16</lower>
            <upper>1e+16</upper>
          </limit>
          <dynamics>
            <spring_reference>0</spring_reference>
            <spring_stiffness>0</spring_stiffness>
          </dynamics>
        </axis>
      </joint>
      <link name='r6_S_roller_link'>
        <pose relative_to='r6_S_roller_joint'>0 0 0 0 -0 0</pose>
        <inertial>
          <pose>0 0 0 0 -0 0</pose>
          <mass>0.009</mass>
          <inertia>
            <ixx>1.257e-06</ixx>
            <ixy>0</ixy>
            <ixz>0</ixz>
            <iyy>3.42e-07</iyy>
            <iyz>0</iyz>
            <izz>1.257e-06</izz>
          </inertia>
        </inertial>
        <collision name='r6_S_roller_link_collision'>
          <pose>0 0 0 0 -0 0</pose>
          <geometry>
            <mesh>
              <scale>1 1 1</scale>
              <uri>/home/yp7/catkin_ws/src/Omni_wheel_robot_GazeboSim/omni_robot_description/meshes/STL/roller/roller.stl</uri>
            </mesh>
          </geometry>
          <max_contacts>10</max_contacts>
          <surface>
            <contact>
              <ode/>
            </contact>
            <bounce/>
            <friction>
              <torsional>
                <ode/>
              </torsional>
              <ode/>
            </friction>
          </surface>
        </collision>
        <visual name='r6_S_roller_link_visual'>
          <pose>0 0 0 0 -0 0</pose>
          <geometry>
            <mesh>
              <scale>1 1 1</scale>
              <uri>/home/yp7/catkin_ws/src/Omni_wheel_robot_GazeboSim/omni_robot_description/meshes/DAE/roller/omni_roller.dae</uri>
            </mesh>
          </geometry>
        </visual>
        <self_collide>0</self_collide>
        <enable_wind>0</enable_wind>
        <kinematic>0</kinematic>
      </link>
      <joint name='r7_S_roller_joint' type='revolute'>
        <pose relative_to='second_wheel_link'>0.022885 0.006 -0.007436 -1.25664 0 1.5708</pose>
        <parent>second_wheel_link</parent>
        <child>r7_S_roller_link</child>
        <axis>
          <xyz>0 1 0</xyz>
          <limit>
            <lower>-1e+16</lower>
            <upper>1e+16</upper>
          </limit>
          <dynamics>
            <spring_reference>0</spring_reference>
            <spring_stiffness>0</spring_stiffness>
          </dynamics>
        </axis>
      </joint>
      <link name='r7_S_roller_link'>
        <pose relative_to='r7_S_roller_joint'>0 0 0 0 -0 0</pose>
        <inertial>
          <pose>0 0 0 0 -0 0</pose>
          <mass>0.009</mass>
          <inertia>
            <ixx>1.257e-06</ixx>
            <ixy>0</ixy>
            <ixz>0</ixz>
            <iyy>3.42e-07</iyy>
            <iyz>0</iyz>
            <izz>1.257e-06</izz>
          </inertia>
        </inertial>
        <collision name='r7_S_roller_link_collision'>
          <pose>0 0 0 0 -0 0</pose>
          <geometry>
            <mesh>
              <scale>1 1 1</scale>
              <uri>/home/yp7/catkin_ws/src/Omni_wheel_robot_GazeboSim/omni_robot_description/meshes/STL/roller/roller.stl</uri>
            </mesh>
          </geometry>
          <max_contacts>10</max_contacts>
          <surface>
            <contact>
              <ode/>
            </contact>
            <bounce/>
            <friction>
              <torsional>
                <ode/>
              </torsional>
              <ode/>
            </friction>
          </surface>
        </collision>
        <visual name='r7_S_roller_link_visual'>
          <pose>0 0 0 0 -0 0</pose>
          <geometry>
            <mesh>
              <scale>1 1 1</scale>
              <uri>/home/yp7/catkin_ws/src/Omni_wheel_robot_GazeboSim/omni_robot_description/meshes/DAE/roller/omni_roller.dae</uri>
            </mesh>
          </geometry>
        </visual>
        <self_collide>0</self_collide>
        <enable_wind>0</enable_wind>
        <kinematic>0</kinematic>
      </link>
      <joint name='r8_S_roller_joint' type='revolute'>
        <pose relative_to='second_wheel_link'>0.014144 0.006 0.019467 -2.51327 -0 1.5708</pose>
        <parent>second_wheel_link</parent>
        <child>r8_S_roller_link</child>
        <axis>
          <xyz>0 1 0</xyz>
          <limit>
            <lower>-1e+16</lower>
            <upper>1e+16</upper>
          </limit>
          <dynamics>
            <spring_reference>0</spring_reference>
            <spring_stiffness>0</spring_stiffness>
          </dynamics>
        </axis>
      </joint>
      <link name='r8_S_roller_link'>
        <pose relative_to='r8_S_roller_joint'>0 0 0 0 -0 0</pose>
        <inertial>
          <pose>0 0 0 0 -0 0</pose>
          <mass>0.009</mass>
          <inertia>
            <ixx>1.257e-06</ixx>
            <ixy>0</ixy>
            <ixz>0</ixz>
            <iyy>3.42e-07</iyy>
            <iyz>0</iyz>
            <izz>1.257e-06</izz>
          </inertia>
        </inertial>
        <collision name='r8_S_roller_link_collision'>
          <pose>0 0 0 0 -0 0</pose>
          <geometry>
            <mesh>
              <scale>1 1 1</scale>
              <uri>/home/yp7/catkin_ws/src/Omni_wheel_robot_GazeboSim/omni_robot_description/meshes/STL/roller/roller.stl</uri>
            </mesh>
          </geometry>
          <max_contacts>10</max_contacts>
          <surface>
            <contact>
              <ode/>
            </contact>
            <bounce/>
            <friction>
              <torsional>
                <ode/>
              </torsional>
              <ode/>
            </friction>
          </surface>
        </collision>
        <visual name='r8_S_roller_link_visual'>
          <pose>0 0 0 0 -0 0</pose>
          <geometry>
            <mesh>
              <scale>1 1 1</scale>
              <uri>/home/yp7/catkin_ws/src/Omni_wheel_robot_GazeboSim/omni_robot_description/meshes/DAE/roller/omni_roller.dae</uri>
            </mesh>
          </geometry>
        </visual>
        <self_collide>0</self_collide>
        <enable_wind>0</enable_wind>
        <kinematic>0</kinematic>
      </link>
      <joint name='r9_S_roller_joint' type='revolute'>
        <pose relative_to='second_wheel_link'>-0.014144 0.006 0.019467 2.51327 -0 1.5708</pose>
        <parent>second_wheel_link</parent>
        <child>r9_S_roller_link</child>
        <axis>
          <xyz>0 1 0</xyz>
          <limit>
            <lower>-1e+16</lower>
            <upper>1e+16</upper>
          </limit>
          <dynamics>
            <spring_reference>0</spring_reference>
            <spring_stiffness>0</spring_stiffness>
          </dynamics>
        </axis>
      </joint>
      <link name='r9_S_roller_link'>
        <pose relative_to='r9_S_roller_joint'>0 0 0 0 -0 0</pose>
        <inertial>
          <pose>0 0 0 0 -0 0</pose>
          <mass>0.009</mass>
          <inertia>
            <ixx>1.257e-06</ixx>
            <ixy>0</ixy>
            <ixz>0</ixz>
            <iyy>3.42e-07</iyy>
            <iyz>0</iyz>
            <izz>1.257e-06</izz>
          </inertia>
        </inertial>
        <collision name='r9_S_roller_link_collision'>
          <pose>0 0 0 0 -0 0</pose>
          <geometry>
            <mesh>
              <scale>1 1 1</scale>
              <uri>/home/yp7/catkin_ws/src/Omni_wheel_robot_GazeboSim/omni_robot_description/meshes/STL/roller/roller.stl</uri>
            </mesh>
          </geometry>
          <max_contacts>10</max_contacts>
          <surface>
            <contact>
              <ode/>
            </contact>
            <bounce/>
            <friction>
              <torsional>
                <ode/>
              </torsional>
              <ode/>
            </friction>
          </surface>
        </collision>
        <visual name='r9_S_roller_link_visual'>
          <pose>0 0 0 0 -0 0</pose>
          <geometry>
            <mesh>
              <scale>1 1 1</scale>
              <uri>/home/yp7/catkin_ws/src/Omni_wheel_robot_GazeboSim/omni_robot_description/meshes/DAE/roller/omni_roller.dae</uri>
            </mesh>
          </geometry>
        </visual>
        <self_collide>0</self_collide>
        <enable_wind>0</enable_wind>
        <kinematic>0</kinematic>
      </link>
      <joint name='third_wheel_joint' type='revolute'>
        <pose relative_to='base_footprint'>0.0762 -0.044 -0.01 0 -0 1.0472</pose>
        <parent>base_footprint</parent>
        <child>third_wheel_link</child>
        <axis>
          <xyz>0 1 0</xyz>
          <limit>
            <effort>100</effort>
            <velocity>100</velocity>
            <lower>-1e+16</lower>
            <upper>1e+16</upper>
          </limit>
          <dynamics>
            <spring_reference>0</spring_reference>
            <spring_stiffness>0</spring_stiffness>
          </dynamics>
        </axis>
      </joint>
      <link name='third_wheel_link'>
        <pose relative_to='third_wheel_joint'>0 0 0 0 -0 0</pose>
        <inertial>
          <pose>0 -0.011 0 0 -0 0</pose>
          <mass>0.25</mass>
          <inertia>
            <ixx>0.00031</ixx>
            <ixy>0</ixy>
            <ixz>0</ixz>
            <iyy>0.0005</iyy>
            <iyz>0</iyz>
            <izz>0.00031</izz>
          </inertia>
        </inertial>
        <collision name='third_wheel_link_collision'>
          <pose>0 0 0 0 -0 0</pose>
          <geometry>
            <mesh>
              <scale>1 1 1</scale>
              <uri>/home/yp7/catkin_ws/src/Omni_wheel_robot_GazeboSim/omni_robot_description/meshes/STL/omni_wheel/omni_wheel.stl</uri>
            </mesh>
          </geometry>
          <surface>
            <contact>
              <ode/>
            </contact>
            <friction>
              <ode>
                <mu>0.8</mu>
                <mu2>0.8</mu2>
              </ode>
              <torsional>
                <ode/>
              </torsional>
            </friction>
            <bounce/>
          </surface>
          <max_contacts>10</max_contacts>
        </collision>
        <visual name='third_wheel_link_visual'>
          <pose>0 0 0 0 -0 0</pose>
          <geometry>
            <mesh>
              <scale>1 1 1</scale>
              <uri>/home/yp7/catkin_ws/src/Omni_wheel_robot_GazeboSim/omni_robot_description/meshes/DAE/omni_wheel/omni_wheel.dae</uri>
            </mesh>
          </geometry>
        </visual>
        <self_collide>0</self_collide>
        <enable_wind>0</enable_wind>
        <kinematic>0</kinematic>
      </link>
      <joint name='r10_T_roller_joint' type='revolute'>
        <pose relative_to='third_wheel_link'>-0.022885 0.006 -0.007436 1.25664 -0 1.5708</pose>
        <parent>third_wheel_link</parent>
        <child>r10_T_roller_link</child>
        <axis>
          <xyz>0 1 0</xyz>
          <limit>
            <lower>-1e+16</lower>
            <upper>1e+16</upper>
          </limit>
          <dynamics>
            <spring_reference>0</spring_reference>
            <spring_stiffness>0</spring_stiffness>
          </dynamics>
        </axis>
      </joint>
      <link name='r10_T_roller_link'>
        <pose relative_to='r10_T_roller_joint'>0 0 0 0 -0 0</pose>
        <inertial>
          <pose>0 0 0 0 -0 0</pose>
          <mass>0.009</mass>
          <inertia>
            <ixx>1.257e-06</ixx>
            <ixy>0</ixy>
            <ixz>0</ixz>
            <iyy>3.42e-07</iyy>
            <iyz>0</iyz>
            <izz>1.257e-06</izz>
          </inertia>
        </inertial>
        <collision name='r10_T_roller_link_collision'>
          <pose>0 0 0 0 -0 0</pose>
          <geometry>
            <mesh>
              <scale>1 1 1</scale>
              <uri>/home/yp7/catkin_ws/src/Omni_wheel_robot_GazeboSim/omni_robot_description/meshes/STL/roller/roller.stl</uri>
            </mesh>
          </geometry>
          <max_contacts>10</max_contacts>
          <surface>
            <contact>
              <ode/>
            </contact>
            <bounce/>
            <friction>
              <torsional>
                <ode/>
              </torsional>
              <ode/>
            </friction>
          </surface>
        </collision>
        <visual name='r10_T_roller_link_visual'>
          <pose>0 0 0 0 -0 0</pose>
          <geometry>
            <mesh>
              <scale>1 1 1</scale>
              <uri>/home/yp7/catkin_ws/src/Omni_wheel_robot_GazeboSim/omni_robot_description/meshes/DAE/roller/omni_roller.dae</uri>
            </mesh>
          </geometry>
        </visual>
        <self_collide>0</self_collide>
        <enable_wind>0</enable_wind>
        <kinematic>0</kinematic>
      </link>
      <joint name='r1_T_roller_joint' type='revolute'>
        <pose relative_to='third_wheel_link'>0 -0.006 0.024063 0 -0 1.5708</pose>
        <parent>third_wheel_link</parent>
        <child>r1_T_roller_link</child>
        <axis>
          <xyz>0 1 0</xyz>
          <limit>
            <lower>-1e+16</lower>
            <upper>1e+16</upper>
          </limit>
          <dynamics>
            <spring_reference>0</spring_reference>
            <spring_stiffness>0</spring_stiffness>
          </dynamics>
        </axis>
      </joint>
      <link name='r1_T_roller_link'>
        <pose relative_to='r1_T_roller_joint'>0 0 0 0 -0 0</pose>
        <inertial>
          <pose>0 0 0 0 -0 0</pose>
          <mass>0.009</mass>
          <inertia>
            <ixx>1.257e-06</ixx>
            <ixy>0</ixy>
            <ixz>0</ixz>
            <iyy>3.42e-07</iyy>
            <iyz>0</iyz>
            <izz>1.257e-06</izz>
          </inertia>
        </inertial>
        <collision name='r1_T_roller_link_collision'>
          <pose>0 0 0 0 -0 0</pose>
          <geometry>
            <mesh>
              <scale>1 1 1</scale>
              <uri>/home/yp7/catkin_ws/src/Omni_wheel_robot_GazeboSim/omni_robot_description/meshes/STL/roller/roller.stl</uri>
            </mesh>
          </geometry>
          <max_contacts>10</max_contacts>
          <surface>
            <contact>
              <ode/>
            </contact>
            <bounce/>
            <friction>
              <torsional>
                <ode/>
              </torsional>
              <ode/>
            </friction>
          </surface>
        </collision>
        <visual name='r1_T_roller_link_visual'>
          <pose>0 0 0 0 -0 0</pose>
          <geometry>
            <mesh>
              <scale>1 1 1</scale>
              <uri>/home/yp7/catkin_ws/src/Omni_wheel_robot_GazeboSim/omni_robot_description/meshes/DAE/roller/omni_roller.dae</uri>
            </mesh>
          </geometry>
        </visual>
        <self_collide>0</self_collide>
        <enable_wind>0</enable_wind>
        <kinematic>0</kinematic>
      </link>
      <joint name='r2_T_roller_joint' type='revolute'>
        <pose relative_to='third_wheel_link'>-0.022885 -0.006 0.007436 -1.25664 0 1.5708</pose>
        <parent>third_wheel_link</parent>
        <child>r2_T_roller_link</child>
        <axis>
          <xyz>0 1 0</xyz>
          <limit>
            <lower>-1e+16</lower>
            <upper>1e+16</upper>
          </limit>
          <dynamics>
            <spring_reference>0</spring_reference>
            <spring_stiffness>0</spring_stiffness>
          </dynamics>
        </axis>
      </joint>
      <link name='r2_T_roller_link'>
        <pose relative_to='r2_T_roller_joint'>0 0 0 0 -0 0</pose>
        <inertial>
          <pose>0 0 0 0 -0 0</pose>
          <mass>0.009</mass>
          <inertia>
            <ixx>1.257e-06</ixx>
            <ixy>0</ixy>
            <ixz>0</ixz>
            <iyy>3.42e-07</iyy>
            <iyz>0</iyz>
            <izz>1.257e-06</izz>
          </inertia>
        </inertial>
        <collision name='r2_T_roller_link_collision'>
          <pose>0 0 0 0 -0 0</pose>
          <geometry>
            <mesh>
              <scale>1 1 1</scale>
              <uri>/home/yp7/catkin_ws/src/Omni_wheel_robot_GazeboSim/omni_robot_description/meshes/STL/roller/roller.stl</uri>
            </mesh>
          </geometry>
          <max_contacts>10</max_contacts>
          <surface>
            <contact>
              <ode/>
            </contact>
            <bounce/>
            <friction>
              <torsional>
                <ode/>
              </torsional>
              <ode/>
            </friction>
          </surface>
        </collision>
        <visual name='r2_T_roller_link_visual'>
          <pose>0 0 0 0 -0 0</pose>
          <geometry>
            <mesh>
              <scale>1 1 1</scale>
              <uri>/home/yp7/catkin_ws/src/Omni_wheel_robot_GazeboSim/omni_robot_description/meshes/DAE/roller/omni_roller.dae</uri>
            </mesh>
          </geometry>
        </visual>
        <self_collide>0</self_collide>
        <enable_wind>0</enable_wind>
        <kinematic>0</kinematic>
      </link>
      <joint name='r3_T_roller_joint' type='revolute'>
        <pose relative_to='third_wheel_link'>-0.014144 -0.006 -0.019467 -2.51327 -0 1.5708</pose>
        <parent>third_wheel_link</parent>
        <child>r3_T_roller_link</child>
        <axis>
          <xyz>0 1 0</xyz>
          <limit>
            <lower>-1e+16</lower>
            <upper>1e+16</upper>
          </limit>
          <dynamics>
            <spring_reference>0</spring_reference>
            <spring_stiffness>0</spring_stiffness>
          </dynamics>
        </axis>
      </joint>
      <link name='r3_T_roller_link'>
        <pose relative_to='r3_T_roller_joint'>0 0 0 0 -0 0</pose>
        <inertial>
          <pose>0 0 0 0 -0 0</pose>
          <mass>0.009</mass>
          <inertia>
            <ixx>1.257e-06</ixx>
            <ixy>0</ixy>
            <ixz>0</ixz>
            <iyy>3.42e-07</iyy>
            <iyz>0</iyz>
            <izz>1.257e-06</izz>
          </inertia>
        </inertial>
        <collision name='r3_T_roller_link_collision'>
          <pose>0 0 0 0 -0 0</pose>
          <geometry>
            <mesh>
              <scale>1 1 1</scale>
              <uri>/home/yp7/catkin_ws/src/Omni_wheel_robot_GazeboSim/omni_robot_description/meshes/STL/roller/roller.stl</uri>
            </mesh>
          </geometry>
          <max_contacts>10</max_contacts>
          <surface>
            <contact>
              <ode/>
            </contact>
            <bounce/>
            <friction>
              <torsional>
                <ode/>
              </torsional>
              <ode/>
            </friction>
          </surface>
        </collision>
        <visual name='r3_T_roller_link_visual'>
          <pose>0 0 0 0 -0 0</pose>
          <geometry>
            <mesh>
              <scale>1 1 1</scale>
              <uri>/home/yp7/catkin_ws/src/Omni_wheel_robot_GazeboSim/omni_robot_description/meshes/DAE/roller/omni_roller.dae</uri>
            </mesh>
          </geometry>
        </visual>
        <self_collide>0</self_collide>
        <enable_wind>0</enable_wind>
        <kinematic>0</kinematic>
      </link>
      <joint name='r4_T_roller_joint' type='revolute'>
        <pose relative_to='third_wheel_link'>0.014144 -0.006 -0.019467 2.51327 -0 1.5708</pose>
        <parent>third_wheel_link</parent>
        <child>r4_T_roller_link</child>
        <axis>
          <xyz>0 1 0</xyz>
          <limit>
            <lower>-1e+16</lower>
            <upper>1e+16</upper>
          </limit>
          <dynamics>
            <spring_reference>0</spring_reference>
            <spring_stiffness>0</spring_stiffness>
          </dynamics>
        </axis>
      </joint>
      <link name='r4_T_roller_link'>
        <pose relative_to='r4_T_roller_joint'>0 0 0 0 -0 0</pose>
        <inertial>
          <pose>0 0 0 0 -0 0</pose>
          <mass>0.009</mass>
          <inertia>
            <ixx>1.257e-06</ixx>
            <ixy>0</ixy>
            <ixz>0</ixz>
            <iyy>3.42e-07</iyy>
            <iyz>0</iyz>
            <izz>1.257e-06</izz>
          </inertia>
        </inertial>
        <collision name='r4_T_roller_link_collision'>
          <pose>0 0 0 0 -0 0</pose>
          <geometry>
            <mesh>
              <scale>1 1 1</scale>
              <uri>/home/yp7/catkin_ws/src/Omni_wheel_robot_GazeboSim/omni_robot_description/meshes/STL/roller/roller.stl</uri>
            </mesh>
          </geometry>
          <max_contacts>10</max_contacts>
          <surface>
            <contact>
              <ode/>
            </contact>
            <bounce/>
            <friction>
              <torsional>
                <ode/>
              </torsional>
              <ode/>
            </friction>
          </surface>
        </collision>
        <visual name='r4_T_roller_link_visual'>
          <pose>0 0 0 0 -0 0</pose>
          <geometry>
            <mesh>
              <scale>1 1 1</scale>
              <uri>/home/yp7/catkin_ws/src/Omni_wheel_robot_GazeboSim/omni_robot_description/meshes/DAE/roller/omni_roller.dae</uri>
            </mesh>
          </geometry>
        </visual>
        <self_collide>0</self_collide>
        <enable_wind>0</enable_wind>
        <kinematic>0</kinematic>
      </link>
      <joint name='r5_T_roller_joint' type='revolute'>
        <pose relative_to='third_wheel_link'>0.022885 -0.006 0.007436 1.25664 -0 1.5708</pose>
        <parent>third_wheel_link</parent>
        <child>r5_T_roller_link</child>
        <axis>
          <xyz>0 1 0</xyz>
          <limit>
            <lower>-1e+16</lower>
            <upper>1e+16</upper>
          </limit>
          <dynamics>
            <spring_reference>0</spring_reference>
            <spring_stiffness>0</spring_stiffness>
          </dynamics>
        </axis>
      </joint>
      <link name='r5_T_roller_link'>
        <pose relative_to='r5_T_roller_joint'>0 0 0 0 -0 0</pose>
        <inertial>
          <pose>0 0 0 0 -0 0</pose>
          <mass>0.009</mass>
          <inertia>
            <ixx>1.257e-06</ixx>
            <ixy>0</ixy>
            <ixz>0</ixz>
            <iyy>3.42e-07</iyy>
            <iyz>0</iyz>
            <izz>1.257e-06</izz>
          </inertia>
        </inertial>
        <collision name='r5_T_roller_link_collision'>
          <pose>0 0 0 0 -0 0</pose>
          <geometry>
            <mesh>
              <scale>1 1 1</scale>
              <uri>/home/yp7/catkin_ws/src/Omni_wheel_robot_GazeboSim/omni_robot_description/meshes/STL/roller/roller.stl</uri>
            </mesh>
          </geometry>
          <max_contacts>10</max_contacts>
          <surface>
            <contact>
              <ode/>
            </contact>
            <bounce/>
            <friction>
              <torsional>
                <ode/>
              </torsional>
              <ode/>
            </friction>
          </surface>
        </collision>
        <visual name='r5_T_roller_link_visual'>
          <pose>0 0 0 0 -0 0</pose>
          <geometry>
            <mesh>
              <scale>1 1 1</scale>
              <uri>/home/yp7/catkin_ws/src/Omni_wheel_robot_GazeboSim/omni_robot_description/meshes/DAE/roller/omni_roller.dae</uri>
            </mesh>
          </geometry>
        </visual>
        <self_collide>0</self_collide>
        <enable_wind>0</enable_wind>
        <kinematic>0</kinematic>
      </link>
      <joint name='r6_T_roller_joint' type='revolute'>
        <pose relative_to='third_wheel_link'>0 0.006 -0.024063 0 -0 1.5708</pose>
        <parent>third_wheel_link</parent>
        <child>r6_T_roller_link</child>
        <axis>
          <xyz>0 1 0</xyz>
          <limit>
            <lower>-1e+16</lower>
            <upper>1e+16</upper>
          </limit>
          <dynamics>
            <spring_reference>0</spring_reference>
            <spring_stiffness>0</spring_stiffness>
          </dynamics>
        </axis>
      </joint>
      <link name='r6_T_roller_link'>
        <pose relative_to='r6_T_roller_joint'>0 0 0 0 -0 0</pose>
        <inertial>
          <pose>0 0 0 0 -0 0</pose>
          <mass>0.009</mass>
          <inertia>
            <ixx>1.257e-06</ixx>
            <ixy>0</ixy>
            <ixz>0</ixz>
            <iyy>3.42e-07</iyy>
            <iyz>0</iyz>
            <izz>1.257e-06</izz>
          </inertia>
        </inertial>
        <collision name='r6_T_roller_link_collision'>
          <pose>0 0 0 0 -0 0</pose>
          <geometry>
            <mesh>
              <scale>1 1 1</scale>
              <uri>/home/yp7/catkin_ws/src/Omni_wheel_robot_GazeboSim/omni_robot_description/meshes/STL/roller/roller.stl</uri>
            </mesh>
          </geometry>
          <max_contacts>10</max_contacts>
          <surface>
            <contact>
              <ode/>
            </contact>
            <bounce/>
            <friction>
              <torsional>
                <ode/>
              </torsional>
              <ode/>
            </friction>
          </surface>
        </collision>
        <visual name='r6_T_roller_link_visual'>
          <pose>0 0 0 0 -0 0</pose>
          <geometry>
            <mesh>
              <scale>1 1 1</scale>
              <uri>/home/yp7/catkin_ws/src/Omni_wheel_robot_GazeboSim/omni_robot_description/meshes/DAE/roller/omni_roller.dae</uri>
            </mesh>
          </geometry>
        </visual>
        <self_collide>0</self_collide>
        <enable_wind>0</enable_wind>
        <kinematic>0</kinematic>
      </link>
      <joint name='r7_T_roller_joint' type='revolute'>
        <pose relative_to='third_wheel_link'>0.022885 0.006 -0.007436 -1.25664 0 1.5708</pose>
        <parent>third_wheel_link</parent>
        <child>r7_T_roller_link</child>
        <axis>
          <xyz>0 1 0</xyz>
          <limit>
            <lower>-1e+16</lower>
            <upper>1e+16</upper>
          </limit>
          <dynamics>
            <spring_reference>0</spring_reference>
            <spring_stiffness>0</spring_stiffness>
          </dynamics>
        </axis>
      </joint>
      <link name='r7_T_roller_link'>
        <pose relative_to='r7_T_roller_joint'>0 0 0 0 -0 0</pose>
        <inertial>
          <pose>0 0 0 0 -0 0</pose>
          <mass>0.009</mass>
          <inertia>
            <ixx>1.257e-06</ixx>
            <ixy>0</ixy>
            <ixz>0</ixz>
            <iyy>3.42e-07</iyy>
            <iyz>0</iyz>
            <izz>1.257e-06</izz>
          </inertia>
        </inertial>
        <collision name='r7_T_roller_link_collision'>
          <pose>0 0 0 0 -0 0</pose>
          <geometry>
            <mesh>
              <scale>1 1 1</scale>
              <uri>/home/yp7/catkin_ws/src/Omni_wheel_robot_GazeboSim/omni_robot_description/meshes/STL/roller/roller.stl</uri>
            </mesh>
          </geometry>
          <max_contacts>10</max_contacts>
          <surface>
            <contact>
              <ode/>
            </contact>
            <bounce/>
            <friction>
              <torsional>
                <ode/>
              </torsional>
              <ode/>
            </friction>
          </surface>
        </collision>
        <visual name='r7_T_roller_link_visual'>
          <pose>0 0 0 0 -0 0</pose>
          <geometry>
            <mesh>
              <scale>1 1 1</scale>
              <uri>/home/yp7/catkin_ws/src/Omni_wheel_robot_GazeboSim/omni_robot_description/meshes/DAE/roller/omni_roller.dae</uri>
            </mesh>
          </geometry>
        </visual>
        <self_collide>0</self_collide>
        <enable_wind>0</enable_wind>
        <kinematic>0</kinematic>
      </link>
      <joint name='r8_T_roller_joint' type='revolute'>
        <pose relative_to='third_wheel_link'>0.014144 0.006 0.019467 -2.51327 -0 1.5708</pose>
        <parent>third_wheel_link</parent>
        <child>r8_T_roller_link</child>
        <axis>
          <xyz>0 1 0</xyz>
          <limit>
            <lower>-1e+16</lower>
            <upper>1e+16</upper>
          </limit>
          <dynamics>
            <spring_reference>0</spring_reference>
            <spring_stiffness>0</spring_stiffness>
          </dynamics>
        </axis>
      </joint>
      <link name='r8_T_roller_link'>
        <pose relative_to='r8_T_roller_joint'>0 0 0 0 -0 0</pose>
        <inertial>
          <pose>0 0 0 0 -0 0</pose>
          <mass>0.009</mass>
          <inertia>
            <ixx>1.257e-06</ixx>
            <ixy>0</ixy>
            <ixz>0</ixz>
            <iyy>3.42e-07</iyy>
            <iyz>0</iyz>
            <izz>1.257e-06</izz>
          </inertia>
        </inertial>
        <collision name='r8_T_roller_link_collision'>
          <pose>0 0 0 0 -0 0</pose>
          <geometry>
            <mesh>
              <scale>1 1 1</scale>
              <uri>/home/yp7/catkin_ws/src/Omni_wheel_robot_GazeboSim/omni_robot_description/meshes/STL/roller/roller.stl</uri>
            </mesh>
          </geometry>
          <max_contacts>10</max_contacts>
          <surface>
            <contact>
              <ode/>
            </contact>
            <bounce/>
            <friction>
              <torsional>
                <ode/>
              </torsional>
              <ode/>
            </friction>
          </surface>
        </collision>
        <visual name='r8_T_roller_link_visual'>
          <pose>0 0 0 0 -0 0</pose>
          <geometry>
            <mesh>
              <scale>1 1 1</scale>
              <uri>/home/yp7/catkin_ws/src/Omni_wheel_robot_GazeboSim/omni_robot_description/meshes/DAE/roller/omni_roller.dae</uri>
            </mesh>
          </geometry>
        </visual>
        <self_collide>0</self_collide>
        <enable_wind>0</enable_wind>
        <kinematic>0</kinematic>
      </link>
      <joint name='r9_T_roller_joint' type='revolute'>
        <pose relative_to='third_wheel_link'>-0.014144 0.006 0.019467 2.51327 -0 1.5708</pose>
        <parent>third_wheel_link</parent>
        <child>r9_T_roller_link</child>
        <axis>
          <xyz>0 1 0</xyz>
          <limit>
            <lower>-1e+16</lower>
            <upper>1e+16</upper>
          </limit>
          <dynamics>
            <spring_reference>0</spring_reference>
            <spring_stiffness>0</spring_stiffness>
          </dynamics>
        </axis>
      </joint>
      <link name='r9_T_roller_link'>
        <pose relative_to='r9_T_roller_joint'>0 0 0 0 -0 0</pose>
        <inertial>
          <pose>0 0 0 0 -0 0</pose>
          <mass>0.009</mass>
          <inertia>
            <ixx>1.257e-06</ixx>
            <ixy>0</ixy>
            <ixz>0</ixz>
            <iyy>3.42e-07</iyy>
            <iyz>0</iyz>
            <izz>1.257e-06</izz>
          </inertia>
        </inertial>
        <collision name='r9_T_roller_link_collision'>
          <pose>0 0 0 0 -0 0</pose>
          <geometry>
            <mesh>
              <scale>1 1 1</scale>
              <uri>/home/yp7/catkin_ws/src/Omni_wheel_robot_GazeboSim/omni_robot_description/meshes/STL/roller/roller.stl</uri>
            </mesh>
          </geometry>
          <max_contacts>10</max_contacts>
          <surface>
            <contact>
              <ode/>
            </contact>
            <bounce/>
            <friction>
              <torsional>
                <ode/>
              </torsional>
              <ode/>
            </friction>
          </surface>
        </collision>
        <visual name='r9_T_roller_link_visual'>
          <pose>0 0 0 0 -0 0</pose>
          <geometry>
            <mesh>
              <scale>1 1 1</scale>
              <uri>/home/yp7/catkin_ws/src/Omni_wheel_robot_GazeboSim/omni_robot_description/meshes/DAE/roller/omni_roller.dae</uri>
            </mesh>
          </geometry>
        </visual>
        <self_collide>0</self_collide>
        <enable_wind>0</enable_wind>
        <kinematic>0</kinematic>
      </link>
      <plugin name='gazebo_ros_control' filename='libgazebo_ros_control.so'>
        <robotNamespace>/robot_omni/</robotNamespace>
      </plugin>
      <frame name='laser_joint' attached_to='first_base_layer_link'>
        <pose>0 0 0.0065 0 -0 1.5707</pose>
      </frame>
      <frame name='laser_scan' attached_to='laser_joint'/>
      <frame name='first_base_layer_joint' attached_to='base_link'>
        <pose>0 0 0.125 0 -0 0</pose>
      </frame>
      <frame name='first_base_layer_link' attached_to='first_base_layer_joint'/>
      <frame name='imu_joint' attached_to='base_link'>
        <pose>0 0 0 0 -0 0</pose>
      </frame>
      <frame name='imu_link' attached_to='imu_joint'/>
      <frame name='base_link_joint' attached_to='base_footprint'>
        <pose>0 0 0 0 -0 0</pose>
      </frame>
      <frame name='base_link' attached_to='base_link_joint'/>
      <frame name='main_camera_joint' attached_to='main_camera_bracket_link'>
        <pose>0 0 0.061 0 0.5236 0</pose>
      </frame>
      <frame name='main_camera_link' attached_to='main_camera_joint'/>
      <pose>0 0 0.2 0 -0 0</pose>
    </model>
  </world>
</sdf>
